Workbook

Sheet Helper-1
A1: {=_xlfn.TEXTJOIN(",", TRUE, IF(Final!$Z$1:$CY$1<>"", COLUMN(Final!$Z$1:$CY$1)-COLUMN(Final!$Z$1)+1, ""))} -> 1,14,58,67,73,76 | B1: Defect type | C1: % | D1: Defect QTY | E1: Rank | F1: Defect Catagory (Sorted) | G1: Defect type (Sorted) | H1: % (Sorted) | I1: Defect QTY (Sorted) | J1: Defect Category | K1: Defect | L1: Defect Qty | M1: Ratio
A2: {=INDEX(Final!$Z$1:$CY$1, LOOKUP(ROW(A1), {1,14,58,67,73,76}, {1,14,58,67,73,76}))} -> A : Fabrics | B2: =INDEX(Final!$Z$2:$CY$2, ROW()-ROW($B$2)+1) -> 1.Damage | C2: =IF(ISBLANK(D2),"",D2/Final!$W$4) -> #DIV/0! | D2: =INDEX(Final!$Z$4:$CY$4, ROW()-ROW($D$2)+1) -> 0 | E2: =IF(C2="",COUNT($C$2:$C$79) + ROW()-ROW($C$2) + 1 - COUNT($C$2:C2),RANK(C2,$C$2:$C$79,0) + COUNTIF($C$2:C2,C2) - 1) -> #DIV/0! | F2: =INDEX($A:$A, MATCH(G2, $B:$B, 0)) -> #N/A | G2: =INDEX($B$2:$B$79,MATCH(ROW()-1,$E$2:$E$79,0)) -> #N/A | H2: =IF(ISBLANK(D2),"",D2/Final!$W$4) -> #DIV/0! | I2: =IF(AND(INDEX($C$2:$C$79,MATCH(ROW()-1,$E$2:$E$79,0))=0,INDEX($D$2:$D$79,MATCH(ROW()-1,$E$2:$E$79,0))=0),"",INDEX($D$2:$D$79,MATCH(ROW()-1,$E$2:$E$79,0))) -> #N/A | J2: {=IF(COUNTIF($I$2:I2, I2)=1, _xlfn.TEXTJOIN(", ", TRUE, _xlfn.UNIQUE(_xlfn._xlws.FILTER($F$2:$F$79, $I$2:$I$79=I2, ""))), "")} -> #N/A | K2: {=IF(COUNTIF($I$2:I2,I2)=1,_xlfn.TEXTJOIN(", ",TRUE,IF($I$2:$I$79=I2,$G$2:$G$79,"")),"")} -> #N/A | L2: =IF(COUNTIF($I$2:I2,I2)=1,I2,"") -> #N/A | M2: =IF(COUNTIF($H$2:H2,H2)=1,H2,"") -> #DIV/0! | O2: =INDEX($J$2:$J$36, MATCH(Q2, $L$2:$L$36, 0)) -> #N/A | P2: =INDEX($K$2:$K$36, MATCH(Q2, $L$2:$L$36, 0)) -> #N/A | Q2: =LARGE($L$2:$L$36, 1) -> #N/A | R2: =LARGE($M$2:$M$36, 1) -> #DIV/0!
A3: {=INDEX(Final!$Z$1:$CY$1, LOOKUP(ROW(A2), {1,14,58,67,73,76}, {1,14,58,67,73,76}))} -> A : Fabrics | B3: =INDEX(Final!$Z$2:$CY$2, ROW()-ROW($B$2)+1) -> 2.Needle breakage defect | C3: =IF(ISBLANK(D3),"",D3/Final!$W$4) -> #DIV/0! | D3: =INDEX(Final!$Z$4:$CY$4, ROW()-ROW($D$2)+1) -> 0 | E3: =IF(C3="",COUNT($C$2:$C$79) + ROW()-ROW($C$2) + 1 - COUNT($C$2:C3),RANK(C3,$C$2:$C$79,0) + COUNTIF($C$2:C3,C3) - 1) -> #DIV/0! | F3: =INDEX($A:$A, MATCH(G3, $B:$B, 0)) -> #N/A | G3: =INDEX($B$2:$B$79,MATCH(ROW()-1,$E$2:$E$79,0)) -> #N/A | H3: =IF(ISBLANK(D3),"",D3/Final!$W$4) -> #DIV/0! | I3: =IF(AND(INDEX($C$2:$C$79,MATCH(ROW()-1,$E$2:$E$79,0))=0,INDEX($D$2:$D$79,MATCH(ROW()-1,$E$2:$E$79,0))=0),"",INDEX($D$2:$D$79,MATCH(ROW()-1,$E$2:$E$79,0))) -> #N/A | J3: {=IF(COUNTIF($I$2:I3, I3)=1, _xlfn.TEXTJOIN(", ", TRUE, _xlfn.UNIQUE(_xlfn._xlws.FILTER($F$2:$F$79, $I$2:$I$79=I3, ""))), "")} | K3: {=IF(COUNTIF($I$2:I3,I3)=1,_xlfn.TEXTJOIN(", ",TRUE,IF($I$2:$I$79=I3,$G$2:$G$79,"")),"")} | L3: {=IF(COUNTIF($I$2:I3,I3)=1,I3,"")} | M3: {=IF(COUNTIF($H$2:H3,H3)=1,H3,"")} | O3: =INDEX($J$2:$J$36, MATCH(Q3, $L$2:$L$36, 0)) -> #N/A | P3: =INDEX($K$2:$K$36, MATCH(Q3, $L$2:$L$36, 0)) -> #N/A | Q3: =LARGE($L$2:$L$36, 2) -> #N/A | R3: =LARGE($M$2:$M$36, 2) -> #DIV/0!
A4: {=INDEX(Final!$Z$1:$CY$1, LOOKUP(ROW(A3), {1,14,58,67,73,76}, {1,14,58,67,73,76}))} -> A : Fabrics | B4: =INDEX(Final!$Z$2:$CY$2, ROW()-ROW($B$2)+1) -> 3.Hole, tear | C4: =IF(ISBLANK(D4),"",D4/Final!$W$4) -> #DIV/0! | D4: =INDEX(Final!$Z$4:$CY$4, ROW()-ROW($D$2)+1) -> 0 | E4: =IF(C4="",COUNT($C$2:$C$79) + ROW()-ROW($C$2) + 1 - COUNT($C$2:C4),RANK(C4,$C$2:$C$79,0) + COUNTIF($C$2:C4,C4) - 1) -> #DIV/0! | F4: =INDEX($A:$A, MATCH(G4, $B:$B, 0)) -> #N/A | G4: =INDEX($B$2:$B$79,MATCH(ROW()-1,$E$2:$E$79,0)) -> #N/A | H4: =IF(ISBLANK(D4),"",D4/Final!$W$4) -> #DIV/0! | I4: =IF(AND(INDEX($C$2:$C$79,MATCH(ROW()-1,$E$2:$E$79,0))=0,INDEX($D$2:$D$79,MATCH(ROW()-1,$E$2:$E$79,0))=0),"",INDEX($D$2:$D$79,MATCH(ROW()-1,$E$2:$E$79,0))) -> #N/A | J4: {=IF(COUNTIF($I$2:I4, I4)=1, _xlfn.TEXTJOIN(", ", TRUE, _xlfn.UNIQUE(_xlfn._xlws.FILTER($F$2:$F$79, $I$2:$I$79=I4, ""))), "")} | K4: {=IF(COUNTIF($I$2:I4,I4)=1,_xlfn.TEXTJOIN(", ",TRUE,IF($I$2:$I$79=I4,$G$2:$G$79,"")),"")} | L4: {=IF(COUNTIF($I$2:I4,I4)=1,I4,"")} | M4: {=IF(COUNTIF($H$2:H4,H4)=1,H4,"")} | O4: =INDEX($J$2:$J$36, MATCH(Q4, $L$2:$L$36, 0)) -> #N/A | P4: =INDEX($K$2:$K$36, MATCH(Q4, $L$2:$L$36, 0)) -> #N/A | Q4: =LARGE($L$2:$L$36, 3) -> #N/A | R4: =LARGE($M$2:$M$36, 3) -> #DIV/0!
A5: {=INDEX(Final!$Z$1:$CY$1, LOOKUP(ROW(A4), {1,14,58,67,73,76}, {1,14,58,67,73,76}))} -> A : Fabrics | B5: =INDEX(Final!$Z$2:$CY$2, ROW()-ROW($B$2)+1) -> 4.NEP | C5: =IF(ISBLANK(D5),"",D5/Final!$W$4) -> #DIV/0! | D5: =INDEX(Final!$Z$4:$CY$4, ROW()-ROW($D$2)+1) -> 0 | E5: =IF(C5="",COUNT($C$2:$C$79) + ROW()-ROW($C$2) + 1 - COUNT($C$2:C5),RANK(C5,$C$2:$C$79,0) + COUNTIF($C$2:C5,C5) - 1) -> #DIV/0! | F5: =INDEX($A:$A, MATCH(G5, $B:$B, 0)) -> #N/A | G5: =INDEX($B$2:$B$79,MATCH(ROW()-1,$E$2:$E$79,0)) -> #N/A | H5: =IF(ISBLANK(D5),"",D5/Final!$W$4) -> #DIV/0! | I5: =IF(AND(INDEX($C$2:$C$79,MATCH(ROW()-1,$E$2:$E$79,0))=0,INDEX($D$2:$D$79,MATCH(ROW()-1,$E$2:$E$79,0))=0),"",INDEX($D$2:$D$79,MATCH(ROW()-1,$E$2:$E$79,0))) -> #N/A | J5: {=IF(COUNTIF($I$2:I5, I5)=1, _xlfn.TEXTJOIN(", ", TRUE, _xlfn.UNIQUE(_xlfn._xlws.FILTER($F$2:$F$79, $I$2:$I$79=I5, ""))), "")} | K5: {=IF(COUNTIF($I$2:I5,I5)=1,_xlfn.TEXTJOIN(", ",TRUE,IF($I$2:$I$79=I5,$G$2:$G$79,"")),"")} | L5: {=IF(COUNTIF($I$2:I5,I5)=1,I5,"")} | M5: {=IF(COUNTIF($H$2:H5,H5)=1,H5,"")} | O5: =INDEX($J$2:$J$36, MATCH(Q5, $L$2:$L$36, 0)) -> #N/A | P5: =INDEX($K$2:$K$36, MATCH(Q5, $L$2:$L$36, 0)) -> #N/A | Q5: =LARGE($L$2:$L$36, 4) -> #N/A | R5: =LARGE($M$2:$M$36, 4) -> #DIV/0!
A6: {=INDEX(Final!$Z$1:$CY$1, LOOKUP(ROW(A5), {1,14,58,67,73,76}, {1,14,58,67,73,76}))} -> A : Fabrics | B6: =INDEX(Final!$Z$2:$CY$2, ROW()-ROW($B$2)+1) -> 5.SLUB | C6: =IF(ISBLANK(D6),"",D6/Final!$W$4) -> #DIV/0! | D6: =INDEX(Final!$Z$4:$CY$4, ROW()-ROW($D$2)+1) -> 0 | E6: =IF(C6="",COUNT($C$2:$C$79) + ROW()-ROW($C$2) + 1 - COUNT($C$2:C6),RANK(C6,$C$2:$C$79,0) + COUNTIF($C$2:C6,C6) - 1) -> #DIV/0! | F6: =INDEX($A:$A, MATCH(G6, $B:$B, 0)) -> #N/A | G6: =INDEX($B$2:$B$79,MATCH(ROW()-1,$E$2:$E$79,0)) -> #N/A | H6: =IF(ISBLANK(D6),"",D6/Final!$W$4) -> #DIV/0! | I6: =IF(AND(INDEX($C$2:$C$79,MATCH(ROW()-1,$E$2:$E$79,0))=0,INDEX($D$2:$D$79,MATCH(ROW()-1,$E$2:$E$79,0))=0),"",INDEX($D$2:$D$79,MATCH(ROW()-1,$E$2:$E$79,0))) -> #N/A | J6: {=IF(COUNTIF($I$2:I6, I6)=1, _xlfn.TEXTJOIN(", ", TRUE, _xlfn.UNIQUE(_xlfn._xlws.FILTER($F$2:$F$79, $I$2:$I$79=I6, ""))), "")} | K6: {=IF(COUNTIF($I$2:I6,I6)=1,_xlfn.TEXTJOIN(", ",TRUE,IF($I$2:$I$79=I6,$G$2:$G$79,"")),"")} | L6: {=IF(COUNTIF($I$2:I6,I6)=1,I6,"")} | M6: {=IF(COUNTIF($H$2:H6,H6)=1,H6,"")} | O6: =INDEX($J$2:$J$36, MATCH(Q6, $L$2:$L$36, 0)) -> #N/A | P6: =INDEX($K$2:$K$36, MATCH(Q6, $L$2:$L$36, 0)) -> #N/A | Q6: =LARGE($L$2:$L$36, 5) -> #N/A | R6: =LARGE($M$2:$M$36, 5) -> #DIV/0!
A7: {=INDEX(Final!$Z$1:$CY$1, LOOKUP(ROW(A6), {1,14,58,67,73,76}, {1,14,58,67,73,76}))} -> A : Fabrics | B7: =INDEX(Final!$Z$2:$CY$2, ROW()-ROW($B$2)+1) -> 6.Weft defect | C7: =IF(ISBLANK(D7),"",D7/Final!$W$4) -> #DIV/0! | D7: =INDEX(Final!$Z$4:$CY$4, ROW()-ROW($D$2)+1) -> 0 | E7: =IF(C7="",COUNT($C$2:$C$79) + ROW()-ROW($C$2) + 1 - COUNT($C$2:C7),RANK(C7,$C$2:$C$79,0) + COUNTIF($C$2:C7,C7) - 1) -> #DIV/0! | F7: =INDEX($A:$A, MATCH(G7, $B:$B, 0)) -> #N/A | G7: =INDEX($B$2:$B$79,MATCH(ROW()-1,$E$2:$E$79,0)) -> #N/A | H7: =IF(ISBLANK(D7),"",D7/Final!$W$4) -> #DIV/0! | I7: =IF(AND(INDEX($C$2:$C$79,MATCH(ROW()-1,$E$2:$E$79,0))=0,INDEX($D$2:$D$79,MATCH(ROW()-1,$E$2:$E$79,0))=0),"",INDEX($D$2:$D$79,MATCH(ROW()-1,$E$2:$E$79,0))) -> #N/A | J7: {=IF(COUNTIF($I$2:I7, I7)=1, _xlfn.TEXTJOIN(", ", TRUE, _xlfn.UNIQUE(_xlfn._xlws.FILTER($F$2:$F$79, $I$2:$I$79=I7, ""))), "")} | K7: {=IF(COUNTIF($I$2:I7,I7)=1,_xlfn.TEXTJOIN(", ",TRUE,IF($I$2:$I$79=I7,$G$2:$G$79,"")),"")} | L7: {=IF(COUNTIF($I$2:I7,I7)=1,I7,"")} | M7: {=IF(COUNTIF($H$2:H7,H7)=1,H7,"")}
A8: {=INDEX(Final!$Z$1:$CY$1, LOOKUP(ROW(A7), {1,14,58,67,73,76}, {1,14,58,67,73,76}))} -> A : Fabrics | B8: =INDEX(Final!$Z$2:$CY$2, ROW()-ROW($B$2)+1) -> 7.Unexpected things interwoven | C8: =IF(ISBLANK(D8),"",D8/Final!$W$4) -> #DIV/0! | D8: =INDEX(Final!$Z$4:$CY$4, ROW()-ROW($D$2)+1) -> 0 | E8: =IF(C8="",COUNT($C$2:$C$79) + ROW()-ROW($C$2) + 1 - COUNT($C$2:C8),RANK(C8,$C$2:$C$79,0) + COUNTIF($C$2:C8,C8) - 1) -> #DIV/0! | F8: =INDEX($A:$A, MATCH(G8, $B:$B, 0)) -> #N/A | G8: =INDEX($B$2:$B$79,MATCH(ROW()-1,$E$2:$E$79,0)) -> #N/A | H8: =IF(ISBLANK(D8),"",D8/Final!$W$4) -> #DIV/0! | I8: =IF(AND(INDEX($C$2:$C$79,MATCH(ROW()-1,$E$2:$E$79,0))=0,INDEX($D$2:$D$79,MATCH(ROW()-1,$E$2:$E$79,0))=0),"",INDEX($D$2:$D$79,MATCH(ROW()-1,$E$2:$E$79,0))) -> #N/A | J8: {=IF(COUNTIF($I$2:I8, I8)=1, _xlfn.TEXTJOIN(", ", TRUE, _xlfn.UNIQUE(_xlfn._xlws.FILTER($F$2:$F$79, $I$2:$I$79=I8, ""))), "")} | K8: {=IF(COUNTIF($I$2:I8,I8)=1,_xlfn.TEXTJOIN(", ",TRUE,IF($I$2:$I$79=I8,$G$2:$G$79,"")),"")} | L8: {=IF(COUNTIF($I$2:I8,I8)=1,I8,"")} | M8: {=IF(COUNTIF($H$2:H8,H8)=1,H8,"")}
A9: {=INDEX(Final!$Z$1:$CY$1, LOOKUP(ROW(A8), {1,14,58,67,73,76}, {1,14,58,67,73,76}))} -> A : Fabrics | B9: =INDEX(Final!$Z$2:$CY$2, ROW()-ROW($B$2)+1) -> 8.Bowing | C9: =IF(ISBLANK(D9),"",D9/Final!$W$4) -> #DIV/0! | D9: =INDEX(Final!$Z$4:$CY$4, ROW()-ROW($D$2)+1) -> 0 | E9: =IF(C9="",COUNT($C$2:$C$79) + ROW()-ROW($C$2) + 1 - COUNT($C$2:C9),RANK(C9,$C$2:$C$79,0) + COUNTIF($C$2:C9,C9) - 1) -> #DIV/0! | F9: =INDEX($A:$A, MATCH(G9, $B:$B, 0)) -> #N/A | G9: =INDEX($B$2:$B$79,MATCH(ROW()-1,$E$2:$E$79,0)) -> #N/A | H9: =IF(ISBLANK(D9),"",D9/Final!$W$4) -> #DIV/0! | I9: =IF(AND(INDEX($C$2:$C$79,MATCH(ROW()-1,$E$2:$E$79,0))=0,INDEX($D$2:$D$79,MATCH(ROW()-1,$E$2:$E$79,0))=0),"",INDEX($D$2:$D$79,MATCH(ROW()-1,$E$2:$E$79,0))) -> #N/A | J9: {=IF(COUNTIF($I$2:I9, I9)=1, _xlfn.TEXTJOIN(", ", TRUE, _xlfn.UNIQUE(_xlfn._xlws.FILTER($F$2:$F$79, $I$2:$I$79=I9, ""))), "")} | K9: {=IF(COUNTIF($I$2:I9,I9)=1,_xlfn.TEXTJOIN(", ",TRUE,IF($I$2:$I$79=I9,$G$2:$G$79,"")),"")} | L9: {=IF(COUNTIF($I$2:I9,I9)=1,I9,"")} | M9: {=IF(COUNTIF($H$2:H9,H9)=1,H9,"")}
A10: {=INDEX(Final!$Z$1:$CY$1, LOOKUP(ROW(A9), {1,14,58,67,73,76}, {1,14,58,67,73,76}))} -> A : Fabrics | B10: =INDEX(Final!$Z$2:$CY$2, ROW()-ROW($B$2)+1) -> 9.Odor | C10: =IF(ISBLANK(D10),"",D10/Final!$W$4) -> #DIV/0! | D10: =INDEX(Final!$Z$4:$CY$4, ROW()-ROW($D$2)+1) -> 0 | E10: =IF(C10="",COUNT($C$2:$C$79) + ROW()-ROW($C$2) + 1 - COUNT($C$2:C10),RANK(C10,$C$2:$C$79,0) + COUNTIF($C$2:C10,C10) - 1) -> #DIV/0! | F10: =INDEX($A:$A, MATCH(G10, $B:$B, 0)) -> #N/A | G10: =INDEX($B$2:$B$79,MATCH(ROW()-1,$E$2:$E$79,0)) -> #N/A | H10: =IF(ISBLANK(D10),"",D10/Final!$W$4) -> #DIV/0! | I10: =IF(AND(INDEX($C$2:$C$79,MATCH(ROW()-1,$E$2:$E$79,0))=0,INDEX($D$2:$D$79,MATCH(ROW()-1,$E$2:$E$79,0))=0),"",INDEX($D$2:$D$79,MATCH(ROW()-1,$E$2:$E$79,0))) -> #N/A | J10: {=IF(COUNTIF($I$2:I10, I10)=1, _xlfn.TEXTJOIN(", ", TRUE, _xlfn.UNIQUE(_xlfn._xlws.FILTER($F$2:$F$79, $I$2:$I$79=I10, ""))), "")} | K10: {=IF(COUNTIF($I$2:I10,I10)=1,_xlfn.TEXTJOIN(", ",TRUE,IF($I$2:$I$79=I10,$G$2:$G$79,"")),"")} | L10: {=IF(COUNTIF($I$2:I10,I10)=1,I10,"")} | M10: {=IF(COUNTIF($H$2:H10,H10)=1,H10,"")}
A11: {=INDEX(Final!$Z$1:$CY$1, LOOKUP(ROW(A10), {1,14,58,67,73,76}, {1,14,58,67,73,76}))} -> A : Fabrics | B11: =INDEX(Final!$Z$2:$CY$2, ROW()-ROW($B$2)+1) -> 10.Uneven dyeing | C11: =IF(ISBLANK(D11),"",D11/Final!$W$4) -> #DIV/0! | D11: =INDEX(Final!$Z$4:$CY$4, ROW()-ROW($D$2)+1) -> 0 | E11: =IF(C11="",COUNT($C$2:$C$79) + ROW()-ROW($C$2) + 1 - COUNT($C$2:C11),RANK(C11,$C$2:$C$79,0) + COUNTIF($C$2:C11,C11) - 1) -> #DIV/0! | F11: =INDEX($A:$A, MATCH(G11, $B:$B, 0)) -> #N/A | G11: =INDEX($B$2:$B$79,MATCH(ROW()-1,$E$2:$E$79,0)) -> #N/A | H11: =IF(ISBLANK(D11),"",D11/Final!$W$4) -> #DIV/0! | I11: =IF(AND(INDEX($C$2:$C$79,MATCH(ROW()-1,$E$2:$E$79,0))=0,INDEX($D$2:$D$79,MATCH(ROW()-1,$E$2:$E$79,0))=0),"",INDEX($D$2:$D$79,MATCH(ROW()-1,$E$2:$E$79,0))) -> #N/A | J11: {=IF(COUNTIF($I$2:I11, I11)=1, _xlfn.TEXTJOIN(", ", TRUE, _xlfn.UNIQUE(_xlfn._xlws.FILTER($F$2:$F$79, $I$2:$I$79=I11, ""))), "")} | K11: {=IF(COUNTIF($I$2:I11,I11)=1,_xlfn.TEXTJOIN(", ",TRUE,IF($I$2:$I$79=I11,$G$2:$G$79,"")),"")} | L11: {=IF(COUNTIF($I$2:I11,I11)=1,I11,"")} | M11: {=IF(COUNTIF($H$2:H11,H11)=1,H11,"")}
A12: {=INDEX(Final!$Z$1:$CY$1, LOOKUP(ROW(A11), {1,14,58,67,73,76}, {1,14,58,67,73,76}))} -> A : Fabrics | B12: =INDEX(Final!$Z$2:$CY$2, ROW()-ROW($B$2)+1) -> 11.Texture, surface defect | C12: =IF(ISBLANK(D12),"",D12/Final!$W$4) -> #DIV/0! | D12: =INDEX(Final!$Z$4:$CY$4, ROW()-ROW($D$2)+1) -> 0 | E12: =IF(C12="",COUNT($C$2:$C$79) + ROW()-ROW($C$2) + 1 - COUNT($C$2:C12),RANK(C12,$C$2:$C$79,0) + COUNTIF($C$2:C12,C12) - 1) -> #DIV/0! | F12: =INDEX($A:$A, MATCH(G12, $B:$B, 0)) -> #N/A | G12: =INDEX($B$2:$B$79,MATCH(ROW()-1,$E$2:$E$79,0)) -> #N/A | H12: =IF(ISBLANK(D12),"",D12/Final!$W$4) -> #DIV/0! | I12: =IF(AND(INDEX($C$2:$C$79,MATCH(ROW()-1,$E$2:$E$79,0))=0,INDEX($D$2:$D$79,MATCH(ROW()-1,$E$2:$E$79,0))=0),"",INDEX($D$2:$D$79,MATCH(ROW()-1,$E$2:$E$79,0))) -> #N/A | J12: {=IF(COUNTIF($I$2:I12, I12)=1, _xlfn.TEXTJOIN(", ", TRUE, _xlfn.UNIQUE(_xlfn._xlws.FILTER($F$2:$F$79, $I$2:$I$79=I12, ""))), "")} | K12: {=IF(COUNTIF($I$2:I12,I12)=1,_xlfn.TEXTJOIN(", ",TRUE,IF($I$2:$I$79=I12,$G$2:$G$79,"")),"")} | L12: {=IF(COUNTIF($I$2:I12,I12)=1,I12,"")} | M12: {=IF(COUNTIF($H$2:H12,H12)=1,H12,"")}
A13: {=INDEX(Final!$Z$1:$CY$1, LOOKUP(ROW(A12), {1,14,58,67,73,76}, {1,14,58,67,73,76}))} -> A : Fabrics | B13: =INDEX(Final!$Z$2:$CY$2, ROW()-ROW($B$2)+1) -> 12.Warp and weft defect | C13: =IF(ISBLANK(D13),"",D13/Final!$W$4) -> #DIV/0! | D13: =INDEX(Final!$Z$4:$CY$4, ROW()-ROW($D$2)+1) -> 0 | E13: =IF(C13="",COUNT($C$2:$C$79) + ROW()-ROW($C$2) + 1 - COUNT($C$2:C13),RANK(C13,$C$2:$C$79,0) + COUNTIF($C$2:C13,C13) - 1) -> #DIV/0! | F13: =INDEX($A:$A, MATCH(G13, $B:$B, 0)) -> #N/A | G13: =INDEX($B$2:$B$79,MATCH(ROW()-1,$E$2:$E$79,0)) -> #N/A | H13: =IF(ISBLANK(D13),"",D13/Final!$W$4) -> #DIV/0! | I13: =IF(AND(INDEX($C$2:$C$79,MATCH(ROW()-1,$E$2:$E$79,0))=0,INDEX($D$2:$D$79,MATCH(ROW()-1,$E$2:$E$79,0))=0),"",INDEX($D$2:$D$79,MATCH(ROW()-1,$E$2:$E$79,0))) -> #N/A | J13: {=IF(COUNTIF($I$2:I13, I13)=1, _xlfn.TEXTJOIN(", ", TRUE, _xlfn.UNIQUE(_xlfn._xlws.FILTER($F$2:$F$79, $I$2:$I$79=I13, ""))), "")} | K13: {=IF(COUNTIF($I$2:I13,I13)=1,_xlfn.TEXTJOIN(", ",TRUE,IF($I$2:$I$79=I13,$G$2:$G$79,"")),"")} | L13: {=IF(COUNTIF($I$2:I13,I13)=1,I13,"")} | M13: {=IF(COUNTIF($H$2:H13,H13)=1,H13,"")}
A14: {=INDEX(Final!$Z$1:$CY$1, LOOKUP(ROW(A13), {1,14,58,67,73,76}, {1,14,58,67,73,76}))} -> A : Fabrics | B14: =INDEX(Final!$Z$2:$CY$2, ROW()-ROW($B$2)+1) -> 13.Yarn severance | C14: =IF(ISBLANK(D14),"",D14/Final!$W$4) -> #DIV/0! | D14: =INDEX(Final!$Z$4:$CY$4, ROW()-ROW($D$2)+1) -> 0 | E14: =IF(C14="",COUNT($C$2:$C$79) + ROW()-ROW($C$2) + 1 - COUNT($C$2:C14),RANK(C14,$C$2:$C$79,0) + COUNTIF($C$2:C14,C14) - 1) -> #DIV/0! | F14: =INDEX($A:$A, MATCH(G14, $B:$B, 0)) -> #N/A | G14: =INDEX($B$2:$B$79,MATCH(ROW()-1,$E$2:$E$79,0)) -> #N/A | H14: =IF(ISBLANK(D14),"",D14/Final!$W$4) -> #DIV/0! | I14: =IF(AND(INDEX($C$2:$C$79,MATCH(ROW()-1,$E$2:$E$79,0))=0,INDEX($D$2:$D$79,MATCH(ROW()-1,$E$2:$E$79,0))=0),"",INDEX($D$2:$D$79,MATCH(ROW()-1,$E$2:$E$79,0))) -> #N/A | J14: {=IF(COUNTIF($I$2:I14, I14)=1, _xlfn.TEXTJOIN(", ", TRUE, _xlfn.UNIQUE(_xlfn._xlws.FILTER($F$2:$F$79, $I$2:$I$79=I14, ""))), "")} | K14: {=IF(COUNTIF($I$2:I14,I14)=1,_xlfn.TEXTJOIN(", ",TRUE,IF($I$2:$I$79=I14,$G$2:$G$79,"")),"")} | L14: {=IF(COUNTIF($I$2:I14,I14)=1,I14,"")} | M14: {=IF(COUNTIF($H$2:H14,H14)=1,H14,"")}
A15: {=INDEX(Final!$Z$1:$CY$1, LOOKUP(ROW(A14), {1,14,58,67,73,76}, {1,14,58,67,73,76}))} -> B : Sewing | B15: =INDEX(Final!$Z$2:$CY$2, ROW()-ROW($B$2)+1) -> 1.Hue difference | C15: =IF(ISBLANK(D15),"",D15/Final!$W$4) -> #DIV/0! | D15: =INDEX(Final!$Z$4:$CY$4, ROW()-ROW($D$2)+1) -> 0 | E15: =IF(C15="",COUNT($C$2:$C$79) + ROW()-ROW($C$2) + 1 - COUNT($C$2:C15),RANK(C15,$C$2:$C$79,0) + COUNTIF($C$2:C15,C15) - 1) -> #DIV/0! | F15: =INDEX($A:$A, MATCH(G15, $B:$B, 0)) -> #N/A | G15: =INDEX($B$2:$B$79,MATCH(ROW()-1,$E$2:$E$79,0)) -> #N/A | H15: =IF(ISBLANK(D15),"",D15/Final!$W$4) -> #DIV/0! | I15: =IF(AND(INDEX($C$2:$C$79,MATCH(ROW()-1,$E$2:$E$79,0))=0,INDEX($D$2:$D$79,MATCH(ROW()-1,$E$2:$E$79,0))=0),"",INDEX($D$2:$D$79,MATCH(ROW()-1,$E$2:$E$79,0))) -> #N/A | J15: {=IF(COUNTIF($I$2:I15, I15)=1, _xlfn.TEXTJOIN(", ", TRUE, _xlfn.UNIQUE(_xlfn._xlws.FILTER($F$2:$F$79, $I$2:$I$79=I15, ""))), "")} | K15: {=IF(COUNTIF($I$2:I15,I15)=1,_xlfn.TEXTJOIN(", ",TRUE,IF($I$2:$I$79=I15,$G$2:$G$79,"")),"")} | L15: {=IF(COUNTIF($I$2:I15,I15)=1,I15,"")} | M15: {=IF(COUNTIF($H$2:H15,H15)=1,H15,"")}
A16: {=INDEX(Final!$Z$1:$CY$1, LOOKUP(ROW(A15), {1,14,58,67,73,76}, {1,14,58,67,73,76}))} -> B : Sewing | B16: =INDEX(Final!$Z$2:$CY$2, ROW()-ROW($B$2)+1) -> 2.Unevenness | C16: =IF(ISBLANK(D16),"",D16/Final!$W$4) -> #DIV/0! | D16: =INDEX(Final!$Z$4:$CY$4, ROW()-ROW($D$2)+1) -> 0 | E16: =IF(C16="",COUNT($C$2:$C$79) + ROW()-ROW($C$2) + 1 - COUNT($C$2:C16),RANK(C16,$C$2:$C$79,0) + COUNTIF($C$2:C16,C16) - 1) -> #DIV/0! | F16: =INDEX($A:$A, MATCH(G16, $B:$B, 0)) -> #N/A | G16: =INDEX($B$2:$B$79,MATCH(ROW()-1,$E$2:$E$79,0)) -> #N/A | H16: =IF(ISBLANK(D16),"",D16/Final!$W$4) -> #DIV/0! | I16: =IF(AND(INDEX($C$2:$C$79,MATCH(ROW()-1,$E$2:$E$79,0))=0,INDEX($D$2:$D$79,MATCH(ROW()-1,$E$2:$E$79,0))=0),"",INDEX($D$2:$D$79,MATCH(ROW()-1,$E$2:$E$79,0))) -> #N/A | J16: {=IF(COUNTIF($I$2:I16, I16)=1, _xlfn.TEXTJOIN(", ", TRUE, _xlfn.UNIQUE(_xlfn._xlws.FILTER($F$2:$F$79, $I$2:$I$79=I16, ""))), "")} | K16: {=IF(COUNTIF($I$2:I16,I16)=1,_xlfn.TEXTJOIN(", ",TRUE,IF($I$2:$I$79=I16,$G$2:$G$79,"")),"")} | L16: {=IF(COUNTIF($I$2:I16,I16)=1,I16,"")} | M16: {=IF(COUNTIF($H$2:H16,H16)=1,H16,"")}
A17: {=INDEX(Final!$Z$1:$CY$1, LOOKUP(ROW(A16), {1,14,58,67,73,76}, {1,14,58,67,73,76}))} -> B : Sewing | B17: =INDEX(Final!$Z$2:$CY$2, ROW()-ROW($B$2)+1) -> 3.Pieces not symmetrical | C17: =IF(ISBLANK(D17),"",D17/Final!$W$4) -> #DIV/0! | D17: =INDEX(Final!$Z$4:$CY$4, ROW()-ROW($D$2)+1) -> 0 | E17: =IF(C17="",COUNT($C$2:$C$79) + ROW()-ROW($C$2) + 1 - COUNT($C$2:C17),RANK(C17,$C$2:$C$79,0) + COUNTIF($C$2:C17,C17) - 1) -> #DIV/0! | F17: =INDEX($A:$A, MATCH(G17, $B:$B, 0)) -> #N/A | G17: =INDEX($B$2:$B$79,MATCH(ROW()-1,$E$2:$E$79,0)) -> #N/A | H17: =IF(ISBLANK(D17),"",D17/Final!$W$4) -> #DIV/0! | I17: =IF(AND(INDEX($C$2:$C$79,MATCH(ROW()-1,$E$2:$E$79,0))=0,INDEX($D$2:$D$79,MATCH(ROW()-1,$E$2:$E$79,0))=0),"",INDEX($D$2:$D$79,MATCH(ROW()-1,$E$2:$E$79,0))) -> #N/A | J17: {=IF(COUNTIF($I$2:I17, I17)=1, _xlfn.TEXTJOIN(", ", TRUE, _xlfn.UNIQUE(_xlfn._xlws.FILTER($F$2:$F$79, $I$2:$I$79=I17, ""))), "")} | K17: {=IF(COUNTIF($I$2:I17,I17)=1,_xlfn.TEXTJOIN(", ",TRUE,IF($I$2:$I$79=I17,$G$2:$G$79,"")),"")} | L17: {=IF(COUNTIF($I$2:I17,I17)=1,I17,"")} | M17: {=IF(COUNTIF($H$2:H17,H17)=1,H17,"")}
A18: {=INDEX(Final!$Z$1:$CY$1, LOOKUP(ROW(A17), {1,14,58,67,73,76}, {1,14,58,67,73,76}))} -> B : Sewing | B18: =INDEX(Final!$Z$2:$CY$2, ROW()-ROW($B$2)+1) -> 4.Deformation (Defect in shape) | C18: =IF(ISBLANK(D18),"",D18/Final!$W$4) -> #DIV/0! | D18: =INDEX(Final!$Z$4:$CY$4, ROW()-ROW($D$2)+1) -> 0 | E18: =IF(C18="",COUNT($C$2:$C$79) + ROW()-ROW($C$2) + 1 - COUNT($C$2:C18),RANK(C18,$C$2:$C$79,0) + COUNTIF($C$2:C18,C18) - 1) -> #DIV/0! | F18: =INDEX($A:$A, MATCH(G18, $B:$B, 0)) -> #N/A | G18: =INDEX($B$2:$B$79,MATCH(ROW()-1,$E$2:$E$79,0)) -> #N/A | H18: =IF(ISBLANK(D18),"",D18/Final!$W$4) -> #DIV/0! | I18: =IF(AND(INDEX($C$2:$C$79,MATCH(ROW()-1,$E$2:$E$79,0))=0,INDEX($D$2:$D$79,MATCH(ROW()-1,$E$2:$E$79,0))=0),"",INDEX($D$2:$D$79,MATCH(ROW()-1,$E$2:$E$79,0))) -> #N/A | J18: {=IF(COUNTIF($I$2:I18, I18)=1, _xlfn.TEXTJOIN(", ", TRUE, _xlfn.UNIQUE(_xlfn._xlws.FILTER($F$2:$F$79, $I$2:$I$79=I18, ""))), "")} | K18: {=IF(COUNTIF($I$2:I18,I18)=1,_xlfn.TEXTJOIN(", ",TRUE,IF($I$2:$I$79=I18,$G$2:$G$79,"")),"")} | L18: {=IF(COUNTIF($I$2:I18,I18)=1,I18,"")} | M18: {=IF(COUNTIF($H$2:H18,H18)=1,H18,"")}
... A38: {=INDEX(Final!$Z$1:$CY$1, LOOKUP(ROW(A37), {1,14,58,67,73,76}, {1,14,58,67,73,76}))} -> B : Sewing | B38: =INDEX(Final!$Z$2:$CY$2, ROW()-ROW($B$2)+1) -> 24.Mislocated bar-tack | C38: =IF(ISBLANK(D38),"",D38/Final!$W$4) -> #DIV/0! | D38: =INDEX(Final!$Z$4:$CY$4, ROW()-ROW($D$2)+1) -> 0 | E38: =IF(C38="",COUNT($C$2:$C$79) + ROW()-ROW($C$2) + 1 - COUNT($C$2:C38),RANK(C38,$C$2:$C$79,0) + COUNTIF($C$2:C38,C38) - 1) -> #DIV/0! | F38: =INDEX($A:$A, MATCH(G38, $B:$B, 0)) -> #N/A | G38: =INDEX($B$2:$B$79,MATCH(ROW()-1,$E$2:$E$79,0)) -> #N/A | H38: =IF(ISBLANK(D38),"",D38/Final!$W$4) -> #DIV/0! | I38: =IF(AND(INDEX($C$2:$C$79,MATCH(ROW()-1,$E$2:$E$79,0))=0,INDEX($D$2:$D$79,MATCH(ROW()-1,$E$2:$E$79,0))=0),"",INDEX($D$2:$D$79,MATCH(ROW()-1,$E$2:$E$79,0))) -> #N/A | J38: {=IF(COUNTIF($I$2:I38, I38)=1, _xlfn.TEXTJOIN(", ", TRUE, _xlfn.UNIQUE(_xlfn._xlws.FILTER($F$2:$F$79, $I$2:$I$79=I38, ""))), "")} | K38: {=IF(COUNTIF($I$2:I38,I38)=1,_xlfn.TEXTJOIN(", ",TRUE,IF($I$2:$I$79=I38,$G$2:$G$79,"")),"")} | L38: {=IF(COUNTIF($I$2:I38,I38)=1,I38,"")} | M38: {=IF(COUNTIF($H$2:H38,H38)=1,H38,"")}
A39: {=INDEX(Final!$Z$1:$CY$1, LOOKUP(ROW(A38), {1,14,58,67,73,76}, {1,14,58,67,73,76}))} -> B : Sewing | B39: =INDEX(Final!$Z$2:$CY$2, ROW()-ROW($B$2)+1) -> 25.Incorrect thread tension | C39: =IF(ISBLANK(D39),"",D39/Final!$W$4) -> #DIV/0! | D39: =INDEX(Final!$Z$4:$CY$4, ROW()-ROW($D$2)+1) -> 0 | E39: =IF(C39="",COUNT($C$2:$C$79) + ROW()-ROW($C$2) + 1 - COUNT($C$2:C39),RANK(C39,$C$2:$C$79,0) + COUNTIF($C$2:C39,C39) - 1) -> #DIV/0! | F39: =INDEX($A:$A, MATCH(G39, $B:$B, 0)) -> #N/A | G39: =INDEX($B$2:$B$79,MATCH(ROW()-1,$E$2:$E$79,0)) -> #N/A | H39: =IF(ISBLANK(D39),"",D39/Final!$W$4) -> #DIV/0! | I39: =IF(AND(INDEX($C$2:$C$79,MATCH(ROW()-1,$E$2:$E$79,0))=0,INDEX($D$2:$D$79,MATCH(ROW()-1,$E$2:$E$79,0))=0),"",INDEX($D$2:$D$79,MATCH(ROW()-1,$E$2:$E$79,0))) -> #N/A
A40: {=INDEX(Final!$Z$1:$CY$1, LOOKUP(ROW(A39), {1,14,58,67,73,76}, {1,14,58,67,73,76}))} -> B : Sewing | B40: =INDEX(Final!$Z$2:$CY$2, ROW()-ROW($B$2)+1) -> 26.Falling off of a thread | C40: =IF(ISBLANK(D40),"",D40/Final!$W$4) -> #DIV/0! | D40: =INDEX(Final!$Z$4:$CY$4, ROW()-ROW($D$2)+1) -> 0 | E40: =IF(C40="",COUNT($C$2:$C$79) + ROW()-ROW($C$2) + 1 - COUNT($C$2:C40),RANK(C40,$C$2:$C$79,0) + COUNTIF($C$2:C40,C40) - 1) -> #DIV/0! | F40: =INDEX($A:$A, MATCH(G40, $B:$B, 0)) -> #N/A | G40: =INDEX($B$2:$B$79,MATCH(ROW()-1,$E$2:$E$79,0)) -> #N/A | H40: =IF(ISBLANK(D40),"",D40/Final!$W$4) -> #DIV/0! | I40: =IF(AND(INDEX($C$2:$C$79,MATCH(ROW()-1,$E$2:$E$79,0))=0,INDEX($D$2:$D$79,MATCH(ROW()-1,$E$2:$E$79,0))=0),"",INDEX($D$2:$D$79,MATCH(ROW()-1,$E$2:$E$79,0))) -> #N/A
A41: {=INDEX(Final!$Z$1:$CY$1, LOOKUP(ROW(A40), {1,14,58,67,73,76}, {1,14,58,67,73,76}))} -> B : Sewing | B41: =INDEX(Final!$Z$2:$CY$2, ROW()-ROW($B$2)+1) -> 27.Lack of reverse stitch | C41: =IF(ISBLANK(D41),"",D41/Final!$W$4) -> #DIV/0! | D41: =INDEX(Final!$Z$4:$CY$4, ROW()-ROW($D$2)+1) -> 0 | E41: =IF(C41="",COUNT($C$2:$C$79) + ROW()-ROW($C$2) + 1 - COUNT($C$2:C41),RANK(C41,$C$2:$C$79,0) + COUNTIF($C$2:C41,C41) - 1) -> #DIV/0! | F41: =INDEX($A:$A, MATCH(G41, $B:$B, 0)) -> #N/A | G41: =INDEX($B$2:$B$79,MATCH(ROW()-1,$E$2:$E$79,0)) -> #N/A | H41: =IF(ISBLANK(D41),"",D41/Final!$W$4) -> #DIV/0! | I41: =IF(AND(INDEX($C$2:$C$79,MATCH(ROW()-1,$E$2:$E$79,0))=0,INDEX($D$2:$D$79,MATCH(ROW()-1,$E$2:$E$79,0))=0),"",INDEX($D$2:$D$79,MATCH(ROW()-1,$E$2:$E$79,0))) -> #N/A
A42: {=INDEX(Final!$Z$1:$CY$1, LOOKUP(ROW(A41), {1,14,58,67,73,76}, {1,14,58,67,73,76}))} -> B : Sewing | B42: =INDEX(Final!$Z$2:$CY$2, ROW()-ROW($B$2)+1) -> 28.Incorrect easing | C42: =IF(ISBLANK(D42),"",D42/Final!$W$4) -> #DIV/0! | D42: =INDEX(Final!$Z$4:$CY$4, ROW()-ROW($D$2)+1) -> 0 | E42: =IF(C42="",COUNT($C$2:$C$79) + ROW()-ROW($C$2) + 1 - COUNT($C$2:C42),RANK(C42,$C$2:$C$79,0) + COUNTIF($C$2:C42,C42) - 1) -> #DIV/0! | F42: =INDEX($A:$A, MATCH(G42, $B:$B, 0)) -> #N/A | G42: =INDEX($B$2:$B$79,MATCH(ROW()-1,$E$2:$E$79,0)) -> #N/A | H42: =IF(ISBLANK(D42),"",D42/Final!$W$4) -> #DIV/0! | I42: =IF(AND(INDEX($C$2:$C$79,MATCH(ROW()-1,$E$2:$E$79,0))=0,INDEX($D$2:$D$79,MATCH(ROW()-1,$E$2:$E$79,0))=0),"",INDEX($D$2:$D$79,MATCH(ROW()-1,$E$2:$E$79,0))) -> #N/A
A43: {=INDEX(Final!$Z$1:$CY$1, LOOKUP(ROW(A42), {1,14,58,67,73,76}, {1,14,58,67,73,76}))} -> B : Sewing | B43: =INDEX(Final!$Z$2:$CY$2, ROW()-ROW($B$2)+1) -> 29.Piecing defect | C43: =IF(ISBLANK(D43),"",D43/Final!$W$4) -> #DIV/0! | D43: =INDEX(Final!$Z$4:$CY$4, ROW()-ROW($D$2)+1) -> 0 | E43: =IF(C43="",COUNT($C$2:$C$79) + ROW()-ROW($C$2) + 1 - COUNT($C$2:C43),RANK(C43,$C$2:$C$79,0) + COUNTIF($C$2:C43,C43) - 1) -> #DIV/0! | F43: =INDEX($A:$A, MATCH(G43, $B:$B, 0)) -> #N/A | G43: =INDEX($B$2:$B$79,MATCH(ROW()-1,$E$2:$E$79,0)) -> #N/A | H43: =IF(ISBLANK(D43),"",D43/Final!$W$4) -> #DIV/0! | I43: =IF(AND(INDEX($C$2:$C$79,MATCH(ROW()-1,$E$2:$E$79,0))=0,INDEX($D$2:$D$79,MATCH(ROW()-1,$E$2:$E$79,0))=0),"",INDEX($D$2:$D$79,MATCH(ROW()-1,$E$2:$E$79,0))) -> #N/A
A44: {=INDEX(Final!$Z$1:$CY$1, LOOKUP(ROW(A43), {1,14,58,67,73,76}, {1,14,58,67,73,76}))} -> B : Sewing | B44: =INDEX(Final!$Z$2:$CY$2, ROW()-ROW($B$2)+1) -> 30.Incorrect lapped seam | C44: =IF(ISBLANK(D44),"",D44/Final!$W$4) -> #DIV/0! | D44: =INDEX(Final!$Z$4:$CY$4, ROW()-ROW($D$2)+1) -> 0 | E44: =IF(C44="",COUNT($C$2:$C$79) + ROW()-ROW($C$2) + 1 - COUNT($C$2:C44),RANK(C44,$C$2:$C$79,0) + COUNTIF($C$2:C44,C44) - 1) -> #DIV/0! | F44: =INDEX($A:$A, MATCH(G44, $B:$B, 0)) -> #N/A | G44: =INDEX($B$2:$B$79,MATCH(ROW()-1,$E$2:$E$79,0)) -> #N/A | H44: =IF(ISBLANK(D44),"",D44/Final!$W$4) -> #DIV/0! | I44: =IF(AND(INDEX($C$2:$C$79,MATCH(ROW()-1,$E$2:$E$79,0))=0,INDEX($D$2:$D$79,MATCH(ROW()-1,$E$2:$E$79,0))=0),"",INDEX($D$2:$D$79,MATCH(ROW()-1,$E$2:$E$79,0))) -> #N/A
A45: {=INDEX(Final!$Z$1:$CY$1, LOOKUP(ROW(A44), {1,14,58,67,73,76}, {1,14,58,67,73,76}))} -> B : Sewing | B45: =INDEX(Final!$Z$2:$CY$2, ROW()-ROW($B$2)+1) -> 31.Incorrect trimming | C45: =IF(ISBLANK(D45),"",D45/Final!$W$4) -> #DIV/0! | D45: =INDEX(Final!$Z$4:$CY$4, ROW()-ROW($D$2)+1) -> 0 | E45: =IF(C45="",COUNT($C$2:$C$79) + ROW()-ROW($C$2) + 1 - COUNT($C$2:C45),RANK(C45,$C$2:$C$79,0) + COUNTIF($C$2:C45,C45) - 1) -> #DIV/0! | F45: =INDEX($A:$A, MATCH(G45, $B:$B, 0)) -> #N/A | G45: =INDEX($B$2:$B$79,MATCH(ROW()-1,$E$2:$E$79,0)) -> #N/A | H45: =IF(ISBLANK(D45),"",D45/Final!$W$4) -> #DIV/0! | I45: =IF(AND(INDEX($C$2:$C$79,MATCH(ROW()-1,$E$2:$E$79,0))=0,INDEX($D$2:$D$79,MATCH(ROW()-1,$E$2:$E$79,0))=0),"",INDEX($D$2:$D$79,MATCH(ROW()-1,$E$2:$E$79,0))) -> #N/A
A46: {=INDEX(Final!$Z$1:$CY$1, LOOKUP(ROW(A45), {1,14,58,67,73,76}, {1,14,58,67,73,76}))} -> B : Sewing | B46: =INDEX(Final!$Z$2:$CY$2, ROW()-ROW($B$2)+1) -> 32.Lack of strength | C46: =IF(ISBLANK(D46),"",D46/Final!$W$4) -> #DIV/0! | D46: =INDEX(Final!$Z$4:$CY$4, ROW()-ROW($D$2)+1) -> 0 | E46: =IF(C46="",COUNT($C$2:$C$79) + ROW()-ROW($C$2) + 1 - COUNT($C$2:C46),RANK(C46,$C$2:$C$79,0) + COUNTIF($C$2:C46,C46) - 1) -> #DIV/0! | F46: =INDEX($A:$A, MATCH(G46, $B:$B, 0)) -> #N/A | G46: =INDEX($B$2:$B$79,MATCH(ROW()-1,$E$2:$E$79,0)) -> #N/A | H46: =IF(ISBLANK(D46),"",D46/Final!$W$4) -> #DIV/0! | I46: =IF(AND(INDEX($C$2:$C$79,MATCH(ROW()-1,$E$2:$E$79,0))=0,INDEX($D$2:$D$79,MATCH(ROW()-1,$E$2:$E$79,0))=0),"",INDEX($D$2:$D$79,MATCH(ROW()-1,$E$2:$E$79,0))) -> #N/A
A47: {=INDEX(Final!$Z$1:$CY$1, LOOKUP(ROW(A46), {1,14,58,67,73,76}, {1,14,58,67,73,76}))} -> B : Sewing | B47: =INDEX(Final!$Z$2:$CY$2, ROW()-ROW($B$2)+1) -> 33.Incorrect buttonhole sewing | C47: =IF(ISBLANK(D47),"",D47/Final!$W$4) -> #DIV/0! | D47: =INDEX(Final!$Z$4:$CY$4, ROW()-ROW($D$2)+1) -> 0 | E47: =IF(C47="",COUNT($C$2:$C$79) + ROW()-ROW($C$2) + 1 - COUNT($C$2:C47),RANK(C47,$C$2:$C$79,0) + COUNTIF($C$2:C47,C47) - 1) -> #DIV/0! | F47: =INDEX($A:$A, MATCH(G47, $B:$B, 0)) -> #N/A | G47: =INDEX($B$2:$B$79,MATCH(ROW()-1,$E$2:$E$79,0)) -> #N/A | H47: =IF(ISBLANK(D47),"",D47/Final!$W$4) -> #DIV/0! | I47: =IF(AND(INDEX($C$2:$C$79,MATCH(ROW()-1,$E$2:$E$79,0))=0,INDEX($D$2:$D$79,MATCH(ROW()-1,$E$2:$E$79,0))=0),"",INDEX($D$2:$D$79,MATCH(ROW()-1,$E$2:$E$79,0))) -> #N/A
A48: {=INDEX(Final!$Z$1:$CY$1, LOOKUP(ROW(A47), {1,14,58,67,73,76}, {1,14,58,67,73,76}))} -> B : Sewing | B48: =INDEX(Final!$Z$2:$CY$2, ROW()-ROW($B$2)+1) -> 34.Incorrect brand label sewing | C48: =IF(ISBLANK(D48),"",D48/Final!$W$4) -> #DIV/0! | D48: =INDEX(Final!$Z$4:$CY$4, ROW()-ROW($D$2)+1) -> 0 | E48: =IF(C48="",COUNT($C$2:$C$79) + ROW()-ROW($C$2) + 1 - COUNT($C$2:C48),RANK(C48,$C$2:$C$79,0) + COUNTIF($C$2:C48,C48) - 1) -> #DIV/0! | F48: =INDEX($A:$A, MATCH(G48, $B:$B, 0)) -> #N/A | G48: =INDEX($B$2:$B$79,MATCH(ROW()-1,$E$2:$E$79,0)) -> #N/A | H48: =IF(ISBLANK(D48),"",D48/Final!$W$4) -> #DIV/0! | I48: =IF(AND(INDEX($C$2:$C$79,MATCH(ROW()-1,$E$2:$E$79,0))=0,INDEX($D$2:$D$79,MATCH(ROW()-1,$E$2:$E$79,0))=0),"",INDEX($D$2:$D$79,MATCH(ROW()-1,$E$2:$E$79,0))) -> #N/A
A49: {=INDEX(Final!$Z$1:$CY$1, LOOKUP(ROW(A48), {1,14,58,67,73,76}, {1,14,58,67,73,76}))} -> B : Sewing | B49: =INDEX(Final!$Z$2:$CY$2, ROW()-ROW($B$2)+1) -> 35.Sewing slip | C49: =IF(ISBLANK(D49),"",D49/Final!$W$4) -> #DIV/0! | D49: =INDEX(Final!$Z$4:$CY$4, ROW()-ROW($D$2)+1) -> 0 | E49: =IF(C49="",COUNT($C$2:$C$79) + ROW()-ROW($C$2) + 1 - COUNT($C$2:C49),RANK(C49,$C$2:$C$79,0) + COUNTIF($C$2:C49,C49) - 1) -> #DIV/0! | F49: =INDEX($A:$A, MATCH(G49, $B:$B, 0)) -> #N/A | G49: =INDEX($B$2:$B$79,MATCH(ROW()-1,$E$2:$E$79,0)) -> #N/A | H49: =IF(ISBLANK(D49),"",D49/Final!$W$4) -> #DIV/0! | I49: =IF(AND(INDEX($C$2:$C$79,MATCH(ROW()-1,$E$2:$E$79,0))=0,INDEX($D$2:$D$79,MATCH(ROW()-1,$E$2:$E$79,0))=0),"",INDEX($D$2:$D$79,MATCH(ROW()-1,$E$2:$E$79,0))) -> #N/A
A50: {=INDEX(Final!$Z$1:$CY$1, LOOKUP(ROW(A49), {1,14,58,67,73,76}, {1,14,58,67,73,76}))} -> B : Sewing | B50: =INDEX(Final!$Z$2:$CY$2, ROW()-ROW($B$2)+1) -> 36.Incorrect position | C50: =IF(ISBLANK(D50),"",D50/Final!$W$4) -> #DIV/0! | D50: =INDEX(Final!$Z$4:$CY$4, ROW()-ROW($D$2)+1) -> 0 | E50: =IF(C50="",COUNT($C$2:$C$79) + ROW()-ROW($C$2) + 1 - COUNT($C$2:C50),RANK(C50,$C$2:$C$79,0) + COUNTIF($C$2:C50,C50) - 1) -> #DIV/0! | F50: =INDEX($A:$A, MATCH(G50, $B:$B, 0)) -> #N/A | G50: =INDEX($B$2:$B$79,MATCH(ROW()-1,$E$2:$E$79,0)) -> #N/A | H50: =IF(ISBLANK(D50),"",D50/Final!$W$4) -> #DIV/0! | I50: =IF(AND(INDEX($C$2:$C$79,MATCH(ROW()-1,$E$2:$E$79,0))=0,INDEX($D$2:$D$79,MATCH(ROW()-1,$E$2:$E$79,0))=0),"",INDEX($D$2:$D$79,MATCH(ROW()-1,$E$2:$E$79,0))) -> #N/A
... A79: {=INDEX(Final!$Z$1:$CY$1, LOOKUP(ROW(A78), {1,14,58,67,73,76}, {1,14,58,67,73,76}))} -> F : Others | B79: =INDEX(Final!$Z$2:$CY$2, ROW()-ROW($B$2)+1) -> 3.Others | C79: =IF(ISBLANK(D79),"",D79/Final!$W$4) -> #DIV/0! | D79: =INDEX(Final!$Z$4:$CY$4, ROW()-ROW($D$2)+1) -> 0 | E79: =IF(C79="",COUNT($C$2:$C$79) + ROW()-ROW($C$2) + 1 - COUNT($C$2:C79),RANK(C79,$C$2:$C$79,0) + COUNTIF($C$2:C79,C79) - 1) -> #DIV/0! | F79: =INDEX($A:$A, MATCH(G79, $B:$B, 0)) -> #N/A | G79: =INDEX($B$2:$B$79,MATCH(ROW()-1,$E$2:$E$79,0)) -> #N/A | H79: =IF(ISBLANK(D79),"",D79/Final!$W$4) -> #DIV/0! | I79: =IF(AND(INDEX($C$2:$C$79,MATCH(ROW()-1,$E$2:$E$79,0))=0,INDEX($D$2:$D$79,MATCH(ROW()-1,$E$2:$E$79,0))=0),"",INDEX($D$2:$D$79,MATCH(ROW()-1,$E$2:$E$79,0))) -> #N/A

Sheet Helper-2
A1: {=_xlfn.TEXTJOIN(",", TRUE, IF('Re-Final'!$Z$1:$CY$1<>"", COLUMN('Re-Final'!$Z$1:$CY$1)-COLUMN('Re-Final'!$Z$1)+1, ""))} -> 1,14,58,67,73,76 | B1: Defect type | C1: % | D1: Defect QTY | E1: Rank | F1: Defect Catagory (Sorted) | G1: Defect type (Sorted) | H1: % (Sorted) | I1: Defect QTY (Sorted) | J1: Defect Category | K1: Defect | L1: Defect Qty | M1: Ratio
A2: {=INDEX('Re-Final'!$Z$1:$CY$1, LOOKUP(ROW(A1), {1,14,58,67,73,76}, {1,14,58,67,73,76}))} -> A : Fabrics | B2: =INDEX('Re-Final'!$Z$2:$CY$2, ROW()-ROW($B$2)+1) -> 1.Damage | C2: =IF(ISBLANK(D2),"",D2/'Re-Final'!$W$4) -> #DIV/0! | D2: =INDEX('Re-Final'!$Z$4:$CY$4, ROW()-ROW($D$2)+1) -> 0 | E2: =IF(C2="",COUNT($C$2:$C$79) + ROW()-ROW($C$2) + 1 - COUNT($C$2:C2),RANK(C2,$C$2:$C$79,0) + COUNTIF($C$2:C2,C2) - 1) -> #DIV/0! | F2: =INDEX($A:$A, MATCH(G2, $B:$B, 0)) -> #N/A | G2: =INDEX($B$2:$B$79,MATCH(ROW()-1,$E$2:$E$79,0)) -> #N/A | H2: =IF(ISBLANK(D2),"",D2/Final!$W$4) -> #DIV/0! | I2: =IF(AND(INDEX($C$2:$C$79,MATCH(ROW()-1,$E$2:$E$79,0))=0,INDEX($D$2:$D$79,MATCH(ROW()-1,$E$2:$E$79,0))=0),"",INDEX($D$2:$D$79,MATCH(ROW()-1,$E$2:$E$79,0))) -> #N/A | J2: {=IF(COUNTIF($I$2:I2, I2)=1, _xlfn.TEXTJOIN(", ", TRUE, _xlfn.UNIQUE(_xlfn._xlws.FILTER($F$2:$F$79, $I$2:$I$79=I2, ""))), "")} -> #N/A | K2: {=IF(COUNTIF($I$2:I2,I2)=1,_xlfn.TEXTJOIN(", ",TRUE,IF($I$2:$I$79=I2,$G$2:$G$79,"")),"")} -> #N/A | L2: =IF(COUNTIF($I$2:I2,I2)=1,I2,"") -> #N/A | M2: =IF(COUNTIF($H$2:H2,H2)=1,H2,"") -> #DIV/0! | O2: =INDEX($J$2:$J$36, MATCH(Q2, $L$2:$L$36, 0)) -> #N/A | P2: =INDEX($K$2:$K$36, MATCH(Q2, $L$2:$L$36, 0)) -> #N/A | Q2: =LARGE($L$2:$L$36, 1) -> #N/A | R2: =LARGE($M$2:$M$36, 1) -> #DIV/0!
A3: {=INDEX('Re-Final'!$Z$1:$CY$1, LOOKUP(ROW(A2), {1,14,58,67,73,76}, {1,14,58,67,73,76}))} -> A : Fabrics | B3: =INDEX('Re-Final'!$Z$2:$CY$2, ROW()-ROW($B$2)+1) -> 2.Needle breakage defect | C3: =IF(ISBLANK(D3),"",D3/'Re-Final'!$W$4) -> #DIV/0! | D3: =INDEX('Re-Final'!$Z$4:$CY$4, ROW()-ROW($D$2)+1) -> 0 | E3: =IF(C3="",COUNT($C$2:$C$79) + ROW()-ROW($C$2) + 1 - COUNT($C$2:C3),RANK(C3,$C$2:$C$79,0) + COUNTIF($C$2:C3,C3) - 1) -> #DIV/0! | F3: =INDEX($A:$A, MATCH(G3, $B:$B, 0)) -> #N/A | G3: =INDEX($B$2:$B$79,MATCH(ROW()-1,$E$2:$E$79,0)) -> #N/A | H3: =IF(ISBLANK(D3),"",D3/Final!$W$4) -> #DIV/0! | I3: =IF(AND(INDEX($C$2:$C$79,MATCH(ROW()-1,$E$2:$E$79,0))=0,INDEX($D$2:$D$79,MATCH(ROW()-1,$E$2:$E$79,0))=0),"",INDEX($D$2:$D$79,MATCH(ROW()-1,$E$2:$E$79,0))) -> #N/A | J3: {=IF(COUNTIF($I$2:I3, I3)=1, _xlfn.TEXTJOIN(", ", TRUE, _xlfn.UNIQUE(_xlfn._xlws.FILTER($F$2:$F$79, $I$2:$I$79=I3, ""))), "")} | K3: {=IF(COUNTIF($I$2:I3,I3)=1,_xlfn.TEXTJOIN(", ",TRUE,IF($I$2:$I$79=I3,$G$2:$G$79,"")),"")} | L3: {=IF(COUNTIF($I$2:I3,I3)=1,I3,"")} | M3: {=IF(COUNTIF($H$2:H3,H3)=1,H3,"")} | O3: =INDEX($J$2:$J$36, MATCH(Q3, $L$2:$L$36, 0)) -> #N/A | P3: =INDEX($K$2:$K$36, MATCH(Q3, $L$2:$L$36, 0)) -> #N/A | Q3: =LARGE($L$2:$L$36, 2) -> #N/A | R3: =LARGE($M$2:$M$36, 2) -> #DIV/0!
A4: {=INDEX('Re-Final'!$Z$1:$CY$1, LOOKUP(ROW(A3), {1,14,58,67,73,76}, {1,14,58,67,73,76}))} -> A : Fabrics | B4: =INDEX('Re-Final'!$Z$2:$CY$2, ROW()-ROW($B$2)+1) -> 3.Hole, tear | C4: =IF(ISBLANK(D4),"",D4/'Re-Final'!$W$4) -> #DIV/0! | D4: =INDEX('Re-Final'!$Z$4:$CY$4, ROW()-ROW($D$2)+1) -> 0 | E4: =IF(C4="",COUNT($C$2:$C$79) + ROW()-ROW($C$2) + 1 - COUNT($C$2:C4),RANK(C4,$C$2:$C$79,0) + COUNTIF($C$2:C4,C4) - 1) -> #DIV/0! | F4: =INDEX($A:$A, MATCH(G4, $B:$B, 0)) -> #N/A | G4: =INDEX($B$2:$B$79,MATCH(ROW()-1,$E$2:$E$79,0)) -> #N/A | H4: =IF(ISBLANK(D4),"",D4/Final!$W$4) -> #DIV/0! | I4: =IF(AND(INDEX($C$2:$C$79,MATCH(ROW()-1,$E$2:$E$79,0))=0,INDEX($D$2:$D$79,MATCH(ROW()-1,$E$2:$E$79,0))=0),"",INDEX($D$2:$D$79,MATCH(ROW()-1,$E$2:$E$79,0))) -> #N/A | J4: {=IF(COUNTIF($I$2:I4, I4)=1, _xlfn.TEXTJOIN(", ", TRUE, _xlfn.UNIQUE(_xlfn._xlws.FILTER($F$2:$F$79, $I$2:$I$79=I4, ""))), "")} | K4: {=IF(COUNTIF($I$2:I4,I4)=1,_xlfn.TEXTJOIN(", ",TRUE,IF($I$2:$I$79=I4,$G$2:$G$79,"")),"")} | L4: {=IF(COUNTIF($I$2:I4,I4)=1,I4,"")} | M4: {=IF(COUNTIF($H$2:H4,H4)=1,H4,"")} | O4: =INDEX($J$2:$J$36, MATCH(Q4, $L$2:$L$36, 0)) -> #N/A | P4: =INDEX($K$2:$K$36, MATCH(Q4, $L$2:$L$36, 0)) -> #N/A | Q4: =LARGE($L$2:$L$36, 3) -> #N/A | R4: =LARGE($M$2:$M$36, 3) -> #DIV/0!
A5: {=INDEX('Re-Final'!$Z$1:$CY$1, LOOKUP(ROW(A4), {1,14,58,67,73,76}, {1,14,58,67,73,76}))} -> A : Fabrics | B5: =INDEX('Re-Final'!$Z$2:$CY$2, ROW()-ROW($B$2)+1) -> 4.NEP | C5: =IF(ISBLANK(D5),"",D5/'Re-Final'!$W$4) -> #DIV/0! | D5: =INDEX('Re-Final'!$Z$4:$CY$4, ROW()-ROW($D$2)+1) -> 0 | E5: =IF(C5="",COUNT($C$2:$C$79) + ROW()-ROW($C$2) + 1 - COUNT($C$2:C5),RANK(C5,$C$2:$C$79,0) + COUNTIF($C$2:C5,C5) - 1) -> #DIV/0! | F5: =INDEX($A:$A, MATCH(G5, $B:$B, 0)) -> #N/A | G5: =INDEX($B$2:$B$79,MATCH(ROW()-1,$E$2:$E$79,0)) -> #N/A | H5: =IF(ISBLANK(D5),"",D5/Final!$W$4) -> #DIV/0! | I5: =IF(AND(INDEX($C$2:$C$79,MATCH(ROW()-1,$E$2:$E$79,0))=0,INDEX($D$2:$D$79,MATCH(ROW()-1,$E$2:$E$79,0))=0),"",INDEX($D$2:$D$79,MATCH(ROW()-1,$E$2:$E$79,0))) -> #N/A | J5: {=IF(COUNTIF($I$2:I5, I5)=1, _xlfn.TEXTJOIN(", ", TRUE, _xlfn.UNIQUE(_xlfn._xlws.FILTER($F$2:$F$79, $I$2:$I$79=I5, ""))), "")} | K5: {=IF(COUNTIF($I$2:I5,I5)=1,_xlfn.TEXTJOIN(", ",TRUE,IF($I$2:$I$79=I5,$G$2:$G$79,"")),"")} | L5: {=IF(COUNTIF($I$2:I5,I5)=1,I5,"")} | M5: {=IF(COUNTIF($H$2:H5,H5)=1,H5,"")} | O5: =INDEX($J$2:$J$36, MATCH(Q5, $L$2:$L$36, 0)) -> #N/A | P5: =INDEX($K$2:$K$36, MATCH(Q5, $L$2:$L$36, 0)) -> #N/A | Q5: =LARGE($L$2:$L$36, 4) -> #N/A | R5: =LARGE($M$2:$M$36, 4) -> #DIV/0!
A6: {=INDEX('Re-Final'!$Z$1:$CY$1, LOOKUP(ROW(A5), {1,14,58,67,73,76}, {1,14,58,67,73,76}))} -> A : Fabrics | B6: =INDEX('Re-Final'!$Z$2:$CY$2, ROW()-ROW($B$2)+1) -> 5.SLUB | C6: =IF(ISBLANK(D6),"",D6/'Re-Final'!$W$4) -> #DIV/0! | D6: =INDEX('Re-Final'!$Z$4:$CY$4, ROW()-ROW($D$2)+1) -> 0 | E6: =IF(C6="",COUNT($C$2:$C$79) + ROW()-ROW($C$2) + 1 - COUNT($C$2:C6),RANK(C6,$C$2:$C$79,0) + COUNTIF($C$2:C6,C6) - 1) -> #DIV/0! | F6: =INDEX($A:$A, MATCH(G6, $B:$B, 0)) -> #N/A | G6: =INDEX($B$2:$B$79,MATCH(ROW()-1,$E$2:$E$79,0)) -> #N/A | H6: =IF(ISBLANK(D6),"",D6/Final!$W$4) -> #DIV/0! | I6: =IF(AND(INDEX($C$2:$C$79,MATCH(ROW()-1,$E$2:$E$79,0))=0,INDEX($D$2:$D$79,MATCH(ROW()-1,$E$2:$E$79,0))=0),"",INDEX($D$2:$D$79,MATCH(ROW()-1,$E$2:$E$79,0))) -> #N/A | J6: {=IF(COUNTIF($I$2:I6, I6)=1, _xlfn.TEXTJOIN(", ", TRUE, _xlfn.UNIQUE(_xlfn._xlws.FILTER($F$2:$F$79, $I$2:$I$79=I6, ""))), "")} | K6: {=IF(COUNTIF($I$2:I6,I6)=1,_xlfn.TEXTJOIN(", ",TRUE,IF($I$2:$I$79=I6,$G$2:$G$79,"")),"")} | L6: {=IF(COUNTIF($I$2:I6,I6)=1,I6,"")} | M6: {=IF(COUNTIF($H$2:H6,H6)=1,H6,"")} | O6: =INDEX($J$2:$J$36, MATCH(Q6, $L$2:$L$36, 0)) -> #N/A | P6: =INDEX($K$2:$K$36, MATCH(Q6, $L$2:$L$36, 0)) -> #N/A | Q6: =LARGE($L$2:$L$36, 5) -> #N/A | R6: =LARGE($M$2:$M$36, 5) -> #DIV/0!
A7: {=INDEX('Re-Final'!$Z$1:$CY$1, LOOKUP(ROW(A6), {1,14,58,67,73,76}, {1,14,58,67,73,76}))} -> A : Fabrics | B7: =INDEX('Re-Final'!$Z$2:$CY$2, ROW()-ROW($B$2)+1) -> 6.Weft defect | C7: =IF(ISBLANK(D7),"",D7/'Re-Final'!$W$4) -> #DIV/0! | D7: =INDEX('Re-Final'!$Z$4:$CY$4, ROW()-ROW($D$2)+1) -> 0 | E7: =IF(C7="",COUNT($C$2:$C$79) + ROW()-ROW($C$2) + 1 - COUNT($C$2:C7),RANK(C7,$C$2:$C$79,0) + COUNTIF($C$2:C7,C7) - 1) -> #DIV/0! | F7: =INDEX($A:$A, MATCH(G7, $B:$B, 0)) -> #N/A | G7: =INDEX($B$2:$B$79,MATCH(ROW()-1,$E$2:$E$79,0)) -> #N/A | H7: =IF(ISBLANK(D7),"",D7/Final!$W$4) -> #DIV/0! | I7: =IF(AND(INDEX($C$2:$C$79,MATCH(ROW()-1,$E$2:$E$79,0))=0,INDEX($D$2:$D$79,MATCH(ROW()-1,$E$2:$E$79,0))=0),"",INDEX($D$2:$D$79,MATCH(ROW()-1,$E$2:$E$79,0))) -> #N/A | J7: {=IF(COUNTIF($I$2:I7, I7)=1, _xlfn.TEXTJOIN(", ", TRUE, _xlfn.UNIQUE(_xlfn._xlws.FILTER($F$2:$F$79, $I$2:$I$79=I7, ""))), "")} | K7: {=IF(COUNTIF($I$2:I7,I7)=1,_xlfn.TEXTJOIN(", ",TRUE,IF($I$2:$I$79=I7,$G$2:$G$79,"")),"")} | L7: {=IF(COUNTIF($I$2:I7,I7)=1,I7,"")} | M7: {=IF(COUNTIF($H$2:H7,H7)=1,H7,"")}
A8: {=INDEX('Re-Final'!$Z$1:$CY$1, LOOKUP(ROW(A7), {1,14,58,67,73,76}, {1,14,58,67,73,76}))} -> A : Fabrics | B8: =INDEX('Re-Final'!$Z$2:$CY$2, ROW()-ROW($B$2)+1) -> 7.Unexpected things interwoven | C8: =IF(ISBLANK(D8),"",D8/'Re-Final'!$W$4) -> #DIV/0! | D8: =INDEX('Re-Final'!$Z$4:$CY$4, ROW()-ROW($D$2)+1) -> 0 | E8: =IF(C8="",COUNT($C$2:$C$79) + ROW()-ROW($C$2) + 1 - COUNT($C$2:C8),RANK(C8,$C$2:$C$79,0) + COUNTIF($C$2:C8,C8) - 1) -> #DIV/0! | F8: =INDEX($A:$A, MATCH(G8, $B:$B, 0)) -> #N/A | G8: =INDEX($B$2:$B$79,MATCH(ROW()-1,$E$2:$E$79,0)) -> #N/A | H8: =IF(ISBLANK(D8),"",D8/Final!$W$4) -> #DIV/0! | I8: =IF(AND(INDEX($C$2:$C$79,MATCH(ROW()-1,$E$2:$E$79,0))=0,INDEX($D$2:$D$79,MATCH(ROW()-1,$E$2:$E$79,0))=0),"",INDEX($D$2:$D$79,MATCH(ROW()-1,$E$2:$E$79,0))) -> #N/A | J8: {=IF(COUNTIF($I$2:I8, I8)=1, _xlfn.TEXTJOIN(", ", TRUE, _xlfn.UNIQUE(_xlfn._xlws.FILTER($F$2:$F$79, $I$2:$I$79=I8, ""))), "")} | K8: {=IF(COUNTIF($I$2:I8,I8)=1,_xlfn.TEXTJOIN(", ",TRUE,IF($I$2:$I$79=I8,$G$2:$G$79,"")),"")} | L8: {=IF(COUNTIF($I$2:I8,I8)=1,I8,"")} | M8: {=IF(COUNTIF($H$2:H8,H8)=1,H8,"")}
A9: {=INDEX('Re-Final'!$Z$1:$CY$1, LOOKUP(ROW(A8), {1,14,58,67,73,76}, {1,14,58,67,73,76}))} -> A : Fabrics | B9: =INDEX('Re-Final'!$Z$2:$CY$2, ROW()-ROW($B$2)+1) -> 8.Bowing | C9: =IF(ISBLANK(D9),"",D9/'Re-Final'!$W$4) -> #DIV/0! | D9: =INDEX('Re-Final'!$Z$4:$CY$4, ROW()-ROW($D$2)+1) -> 0 | E9: =IF(C9="",COUNT($C$2:$C$79) + ROW()-ROW($C$2) + 1 - COUNT($C$2:C9),RANK(C9,$C$2:$C$79,0) + COUNTIF($C$2:C9,C9) - 1) -> #DIV/0! | F9: =INDEX($A:$A, MATCH(G9, $B:$B, 0)) -> #N/A | G9: =INDEX($B$2:$B$79,MATCH(ROW()-1,$E$2:$E$79,0)) -> #N/A | H9: =IF(ISBLANK(D9),"",D9/Final!$W$4) -> #DIV/0! | I9: =IF(AND(INDEX($C$2:$C$79,MATCH(ROW()-1,$E$2:$E$79,0))=0,INDEX($D$2:$D$79,MATCH(ROW()-1,$E$2:$E$79,0))=0),"",INDEX($D$2:$D$79,MATCH(ROW()-1,$E$2:$E$79,0))) -> #N/A | J9: {=IF(COUNTIF($I$2:I9, I9)=1, _xlfn.TEXTJOIN(", ", TRUE, _xlfn.UNIQUE(_xlfn._xlws.FILTER($F$2:$F$79, $I$2:$I$79=I9, ""))), "")} | K9: {=IF(COUNTIF($I$2:I9,I9)=1,_xlfn.TEXTJOIN(", ",TRUE,IF($I$2:$I$79=I9,$G$2:$G$79,"")),"")} | L9: {=IF(COUNTIF($I$2:I9,I9)=1,I9,"")} | M9: {=IF(COUNTIF($H$2:H9,H9)=1,H9,"")}
A10: {=INDEX('Re-Final'!$Z$1:$CY$1, LOOKUP(ROW(A9), {1,14,58,67,73,76}, {1,14,58,67,73,76}))} -> A : Fabrics | B10: =INDEX('Re-Final'!$Z$2:$CY$2, ROW()-ROW($B$2)+1) -> 9.Odor | C10: =IF(ISBLANK(D10),"",D10/'Re-Final'!$W$4) -> #DIV/0! | D10: =INDEX('Re-Final'!$Z$4:$CY$4, ROW()-ROW($D$2)+1) -> 0 | E10: =IF(C10="",COUNT($C$2:$C$79) + ROW()-ROW($C$2) + 1 - COUNT($C$2:C10),RANK(C10,$C$2:$C$79,0) + COUNTIF($C$2:C10,C10) - 1) -> #DIV/0! | F10: =INDEX($A:$A, MATCH(G10, $B:$B, 0)) -> #N/A | G10: =INDEX($B$2:$B$79,MATCH(ROW()-1,$E$2:$E$79,0)) -> #N/A | H10: =IF(ISBLANK(D10),"",D10/Final!$W$4) -> #DIV/0! | I10: =IF(AND(INDEX($C$2:$C$79,MATCH(ROW()-1,$E$2:$E$79,0))=0,INDEX($D$2:$D$79,MATCH(ROW()-1,$E$2:$E$79,0))=0),"",INDEX($D$2:$D$79,MATCH(ROW()-1,$E$2:$E$79,0))) -> #N/A | J10: {=IF(COUNTIF($I$2:I10, I10)=1, _xlfn.TEXTJOIN(", ", TRUE, _xlfn.UNIQUE(_xlfn._xlws.FILTER($F$2:$F$79, $I$2:$I$79=I10, ""))), "")} | K10: {=IF(COUNTIF($I$2:I10,I10)=1,_xlfn.TEXTJOIN(", ",TRUE,IF($I$2:$I$79=I10,$G$2:$G$79,"")),"")} | L10: {=IF(COUNTIF($I$2:I10,I10)=1,I10,"")} | M10: {=IF(COUNTIF($H$2:H10,H10)=1,H10,"")}
A11: {=INDEX('Re-Final'!$Z$1:$CY$1, LOOKUP(ROW(A10), {1,14,58,67,73,76}, {1,14,58,67,73,76}))} -> A : Fabrics | B11: =INDEX('Re-Final'!$Z$2:$CY$2, ROW()-ROW($B$2)+1) -> 10.Uneven dyeing | C11: =IF(ISBLANK(D11),"",D11/'Re-Final'!$W$4) -> #DIV/0! | D11: =INDEX('Re-Final'!$Z$4:$CY$4, ROW()-ROW($D$2)+1) -> 0 | E11: =IF(C11="",COUNT($C$2:$C$79) + ROW()-ROW($C$2) + 1 - COUNT($C$2:C11),RANK(C11,$C$2:$C$79,0) + COUNTIF($C$2:C11,C11) - 1) -> #DIV/0! | F11: =INDEX($A:$A, MATCH(G11, $B:$B, 0)) -> #N/A | G11: =INDEX($B$2:$B$79,MATCH(ROW()-1,$E$2:$E$79,0)) -> #N/A | H11: =IF(ISBLANK(D11),"",D11/Final!$W$4) -> #DIV/0! | I11: =IF(AND(INDEX($C$2:$C$79,MATCH(ROW()-1,$E$2:$E$79,0))=0,INDEX($D$2:$D$79,MATCH(ROW()-1,$E$2:$E$79,0))=0),"",INDEX($D$2:$D$79,MATCH(ROW()-1,$E$2:$E$79,0))) -> #N/A | J11: {=IF(COUNTIF($I$2:I11, I11)=1, _xlfn.TEXTJOIN(", ", TRUE, _xlfn.UNIQUE(_xlfn._xlws.FILTER($F$2:$F$79, $I$2:$I$79=I11, ""))), "")} | K11: {=IF(COUNTIF($I$2:I11,I11)=1,_xlfn.TEXTJOIN(", ",TRUE,IF($I$2:$I$79=I11,$G$2:$G$79,"")),"")} | L11: {=IF(COUNTIF($I$2:I11,I11)=1,I11,"")} | M11: {=IF(COUNTIF($H$2:H11,H11)=1,H11,"")}
A12: {=INDEX('Re-Final'!$Z$1:$CY$1, LOOKUP(ROW(A11), {1,14,58,67,73,76}, {1,14,58,67,73,76}))} -> A : Fabrics | B12: =INDEX('Re-Final'!$Z$2:$CY$2, ROW()-ROW($B$2)+1) -> 11.Texture, surface defect | C12: =IF(ISBLANK(D12),"",D12/'Re-Final'!$W$4) -> #DIV/0! | D12: =INDEX('Re-Final'!$Z$4:$CY$4, ROW()-ROW($D$2)+1) -> 0 | E12: =IF(C12="",COUNT($C$2:$C$79) + ROW()-ROW($C$2) + 1 - COUNT($C$2:C12),RANK(C12,$C$2:$C$79,0) + COUNTIF($C$2:C12,C12) - 1) -> #DIV/0! | F12: =INDEX($A:$A, MATCH(G12, $B:$B, 0)) -> #N/A | G12: =INDEX($B$2:$B$79,MATCH(ROW()-1,$E$2:$E$79,0)) -> #N/A | H12: =IF(ISBLANK(D12),"",D12/Final!$W$4) -> #DIV/0! | I12: =IF(AND(INDEX($C$2:$C$79,MATCH(ROW()-1,$E$2:$E$79,0))=0,INDEX($D$2:$D$79,MATCH(ROW()-1,$E$2:$E$79,0))=0),"",INDEX($D$2:$D$79,MATCH(ROW()-1,$E$2:$E$79,0))) -> #N/A | J12: {=IF(COUNTIF($I$2:I12, I12)=1, _xlfn.TEXTJOIN(", ", TRUE, _xlfn.UNIQUE(_xlfn._xlws.FILTER($F$2:$F$79, $I$2:$I$79=I12, ""))), "")} | K12: {=IF(COUNTIF($I$2:I12,I12)=1,_xlfn.TEXTJOIN(", ",TRUE,IF($I$2:$I$79=I12,$G$2:$G$79,"")),"")} | L12: {=IF(COUNTIF($I$2:I12,I12)=1,I12,"")} | M12: {=IF(COUNTIF($H$2:H12,H12)=1,H12,"")}
A13: {=INDEX('Re-Final'!$Z$1:$CY$1, LOOKUP(ROW(A12), {1,14,58,67,73,76}, {1,14,58,67,73,76}))} -> A : Fabrics | B13: =INDEX('Re-Final'!$Z$2:$CY$2, ROW()-ROW($B$2)+1) -> 12.Warp and weft defect | C13: =IF(ISBLANK(D13),"",D13/'Re-Final'!$W$4) -> #DIV/0! | D13: =INDEX('Re-Final'!$Z$4:$CY$4, ROW()-ROW($D$2)+1) -> 0 | E13: =IF(C13="",COUNT($C$2:$C$79) + ROW()-ROW($C$2) + 1 - COUNT($C$2:C13),RANK(C13,$C$2:$C$79,0) + COUNTIF($C$2:C13,C13) - 1) -> #DIV/0! | F13: =INDEX($A:$A, MATCH(G13, $B:$B, 0)) -> #N/A | G13: =INDEX($B$2:$B$79,MATCH(ROW()-1,$E$2:$E$79,0)) -> #N/A | H13: =IF(ISBLANK(D13),"",D13/Final!$W$4) -> #DIV/0! | I13: =IF(AND(INDEX($C$2:$C$79,MATCH(ROW()-1,$E$2:$E$79,0))=0,INDEX($D$2:$D$79,MATCH(ROW()-1,$E$2:$E$79,0))=0),"",INDEX($D$2:$D$79,MATCH(ROW()-1,$E$2:$E$79,0))) -> #N/A | J13: {=IF(COUNTIF($I$2:I13, I13)=1, _xlfn.TEXTJOIN(", ", TRUE, _xlfn.UNIQUE(_xlfn._xlws.FILTER($F$2:$F$79, $I$2:$I$79=I13, ""))), "")} | K13: {=IF(COUNTIF($I$2:I13,I13)=1,_xlfn.TEXTJOIN(", ",TRUE,IF($I$2:$I$79=I13,$G$2:$G$79,"")),"")} | L13: {=IF(COUNTIF($I$2:I13,I13)=1,I13,"")} | M13: {=IF(COUNTIF($H$2:H13,H13)=1,H13,"")}
A14: {=INDEX('Re-Final'!$Z$1:$CY$1, LOOKUP(ROW(A13), {1,14,58,67,73,76}, {1,14,58,67,73,76}))} -> A : Fabrics | B14: =INDEX('Re-Final'!$Z$2:$CY$2, ROW()-ROW($B$2)+1) -> 13.Yarn severance | C14: =IF(ISBLANK(D14),"",D14/'Re-Final'!$W$4) -> #DIV/0! | D14: =INDEX('Re-Final'!$Z$4:$CY$4, ROW()-ROW($D$2)+1) -> 0 | E14: =IF(C14="",COUNT($C$2:$C$79) + ROW()-ROW($C$2) + 1 - COUNT($C$2:C14),RANK(C14,$C$2:$C$79,0) + COUNTIF($C$2:C14,C14) - 1) -> #DIV/0! | F14: =INDEX($A:$A, MATCH(G14, $B:$B, 0)) -> #N/A | G14: =INDEX($B$2:$B$79,MATCH(ROW()-1,$E$2:$E$79,0)) -> #N/A | H14: =IF(ISBLANK(D14),"",D14/Final!$W$4) -> #DIV/0! | I14: =IF(AND(INDEX($C$2:$C$79,MATCH(ROW()-1,$E$2:$E$79,0))=0,INDEX($D$2:$D$79,MATCH(ROW()-1,$E$2:$E$79,0))=0),"",INDEX($D$2:$D$79,MATCH(ROW()-1,$E$2:$E$79,0))) -> #N/A | J14: {=IF(COUNTIF($I$2:I14, I14)=1, _xlfn.TEXTJOIN(", ", TRUE, _xlfn.UNIQUE(_xlfn._xlws.FILTER($F$2:$F$79, $I$2:$I$79=I14, ""))), "")} | K14: {=IF(COUNTIF($I$2:I14,I14)=1,_xlfn.TEXTJOIN(", ",TRUE,IF($I$2:$I$79=I14,$G$2:$G$79,"")),"")} | L14: {=IF(COUNTIF($I$2:I14,I14)=1,I14,"")} | M14: {=IF(COUNTIF($H$2:H14,H14)=1,H14,"")}
A15: {=INDEX('Re-Final'!$Z$1:$CY$1, LOOKUP(ROW(A14), {1,14,58,67,73,76}, {1,14,58,67,73,76}))} -> B : Sewing | B15: =INDEX('Re-Final'!$Z$2:$CY$2, ROW()-ROW($B$2)+1) -> 1.Hue difference | C15: =IF(ISBLANK(D15),"",D15/'Re-Final'!$W$4) -> #DIV/0! | D15: =INDEX('Re-Final'!$Z$4:$CY$4, ROW()-ROW($D$2)+1) -> 0 | E15: =IF(C15="",COUNT($C$2:$C$79) + ROW()-ROW($C$2) + 1 - COUNT($C$2:C15),RANK(C15,$C$2:$C$79,0) + COUNTIF($C$2:C15,C15) - 1) -> #DIV/0! | F15: =INDEX($A:$A, MATCH(G15, $B:$B, 0)) -> #N/A | G15: =INDEX($B$2:$B$79,MATCH(ROW()-1,$E$2:$E$79,0)) -> #N/A | H15: =IF(ISBLANK(D15),"",D15/Final!$W$4) -> #DIV/0! | I15: =IF(AND(INDEX($C$2:$C$79,MATCH(ROW()-1,$E$2:$E$79,0))=0,INDEX($D$2:$D$79,MATCH(ROW()-1,$E$2:$E$79,0))=0),"",INDEX($D$2:$D$79,MATCH(ROW()-1,$E$2:$E$79,0))) -> #N/A | J15: {=IF(COUNTIF($I$2:I15, I15)=1, _xlfn.TEXTJOIN(", ", TRUE, _xlfn.UNIQUE(_xlfn._xlws.FILTER($F$2:$F$79, $I$2:$I$79=I15, ""))), "")} | K15: {=IF(COUNTIF($I$2:I15,I15)=1,_xlfn.TEXTJOIN(", ",TRUE,IF($I$2:$I$79=I15,$G$2:$G$79,"")),"")} | L15: {=IF(COUNTIF($I$2:I15,I15)=1,I15,"")} | M15: {=IF(COUNTIF($H$2:H15,H15)=1,H15,"")}
A16: {=INDEX('Re-Final'!$Z$1:$CY$1, LOOKUP(ROW(A15), {1,14,58,67,73,76}, {1,14,58,67,73,76}))} -> B : Sewing | B16: =INDEX('Re-Final'!$Z$2:$CY$2, ROW()-ROW($B$2)+1) -> 2.Unevenness | C16: =IF(ISBLANK(D16),"",D16/'Re-Final'!$W$4) -> #DIV/0! | D16: =INDEX('Re-Final'!$Z$4:$CY$4, ROW()-ROW($D$2)+1) -> 0 | E16: =IF(C16="",COUNT($C$2:$C$79) + ROW()-ROW($C$2) + 1 - COUNT($C$2:C16),RANK(C16,$C$2:$C$79,0) + COUNTIF($C$2:C16,C16) - 1) -> #DIV/0! | F16: =INDEX($A:$A, MATCH(G16, $B:$B, 0)) -> #N/A | G16: =INDEX($B$2:$B$79,MATCH(ROW()-1,$E$2:$E$79,0)) -> #N/A | H16: =IF(ISBLANK(D16),"",D16/Final!$W$4) -> #DIV/0! | I16: =IF(AND(INDEX($C$2:$C$79,MATCH(ROW()-1,$E$2:$E$79,0))=0,INDEX($D$2:$D$79,MATCH(ROW()-1,$E$2:$E$79,0))=0),"",INDEX($D$2:$D$79,MATCH(ROW()-1,$E$2:$E$79,0))) -> #N/A | J16: {=IF(COUNTIF($I$2:I16, I16)=1, _xlfn.TEXTJOIN(", ", TRUE, _xlfn.UNIQUE(_xlfn._xlws.FILTER($F$2:$F$79, $I$2:$I$79=I16, ""))), "")} | K16: {=IF(COUNTIF($I$2:I16,I16)=1,_xlfn.TEXTJOIN(", ",TRUE,IF($I$2:$I$79=I16,$G$2:$G$79,"")),"")} | L16: {=IF(COUNTIF($I$2:I16,I16)=1,I16,"")} | M16: {=IF(COUNTIF($H$2:H16,H16)=1,H16,"")}
A17: {=INDEX('Re-Final'!$Z$1:$CY$1, LOOKUP(ROW(A16), {1,14,58,67,73,76}, {1,14,58,67,73,76}))} -> B : Sewing | B17: =INDEX('Re-Final'!$Z$2:$CY$2, ROW()-ROW($B$2)+1) -> 3.Pieces not symmetrical | C17: =IF(ISBLANK(D17),"",D17/'Re-Final'!$W$4) -> #DIV/0! | D17: =INDEX('Re-Final'!$Z$4:$CY$4, ROW()-ROW($D$2)+1) -> 0 | E17: =IF(C17="",COUNT($C$2:$C$79) + ROW()-ROW($C$2) + 1 - COUNT($C$2:C17),RANK(C17,$C$2:$C$79,0) + COUNTIF($C$2:C17,C17) - 1) -> #DIV/0! | F17: =INDEX($A:$A, MATCH(G17, $B:$B, 0)) -> #N/A | G17: =INDEX($B$2:$B$79,MATCH(ROW()-1,$E$2:$E$79,0)) -> #N/A | H17: =IF(ISBLANK(D17),"",D17/Final!$W$4) -> #DIV/0! | I17: =IF(AND(INDEX($C$2:$C$79,MATCH(ROW()-1,$E$2:$E$79,0))=0,INDEX($D$2:$D$79,MATCH(ROW()-1,$E$2:$E$79,0))=0),"",INDEX($D$2:$D$79,MATCH(ROW()-1,$E$2:$E$79,0))) -> #N/A | J17: {=IF(COUNTIF($I$2:I17, I17)=1, _xlfn.TEXTJOIN(", ", TRUE, _xlfn.UNIQUE(_xlfn._xlws.FILTER($F$2:$F$79, $I$2:$I$79=I17, ""))), "")} | K17: {=IF(COUNTIF($I$2:I17,I17)=1,_xlfn.TEXTJOIN(", ",TRUE,IF($I$2:$I$79=I17,$G$2:$G$79,"")),"")} | L17: {=IF(COUNTIF($I$2:I17,I17)=1,I17,"")} | M17: {=IF(COUNTIF($H$2:H17,H17)=1,H17,"")}
A18: {=INDEX('Re-Final'!$Z$1:$CY$1, LOOKUP(ROW(A17), {1,14,58,67,73,76}, {1,14,58,67,73,76}))} -> B : Sewing | B18: =INDEX('Re-Final'!$Z$2:$CY$2, ROW()-ROW($B$2)+1) -> 4.Deformation (Defect in shape) | C18: =IF(ISBLANK(D18),"",D18/'Re-Final'!$W$4) -> #DIV/0! | D18: =INDEX('Re-Final'!$Z$4:$CY$4, ROW()-ROW($D$2)+1) -> 0 | E18: =IF(C18="",COUNT($C$2:$C$79) + ROW()-ROW($C$2) + 1 - COUNT($C$2:C18),RANK(C18,$C$2:$C$79,0) + COUNTIF($C$2:C18,C18) - 1) -> #DIV/0! | F18: =INDEX($A:$A, MATCH(G18, $B:$B, 0)) -> #N/A | G18: =INDEX($B$2:$B$79,MATCH(ROW()-1,$E$2:$E$79,0)) -> #N/A | H18: =IF(ISBLANK(D18),"",D18/Final!$W$4) -> #DIV/0! | I18: =IF(AND(INDEX($C$2:$C$79,MATCH(ROW()-1,$E$2:$E$79,0))=0,INDEX($D$2:$D$79,MATCH(ROW()-1,$E$2:$E$79,0))=0),"",INDEX($D$2:$D$79,MATCH(ROW()-1,$E$2:$E$79,0))) -> #N/A | J18: {=IF(COUNTIF($I$2:I18, I18)=1, _xlfn.TEXTJOIN(", ", TRUE, _xlfn.UNIQUE(_xlfn._xlws.FILTER($F$2:$F$79, $I$2:$I$79=I18, ""))), "")} | K18: {=IF(COUNTIF($I$2:I18,I18)=1,_xlfn.TEXTJOIN(", ",TRUE,IF($I$2:$I$79=I18,$G$2:$G$79,"")),"")} | L18: {=IF(COUNTIF($I$2:I18,I18)=1,I18,"")} | M18: {=IF(COUNTIF($H$2:H18,H18)=1,H18,"")}
... A38: {=INDEX('Re-Final'!$Z$1:$CY$1, LOOKUP(ROW(A37), {1,14,58,67,73,76}, {1,14,58,67,73,76}))} -> B : Sewing | B38: =INDEX('Re-Final'!$Z$2:$CY$2, ROW()-ROW($B$2)+1) -> 24.Mislocated bar-tack | C38: =IF(ISBLANK(D38),"",D38/'Re-Final'!$W$4) -> #DIV/0! | D38: =INDEX('Re-Final'!$Z$4:$CY$4, ROW()-ROW($D$2)+1) -> 0 | E38: =IF(C38="",COUNT($C$2:$C$79) + ROW()-ROW($C$2) + 1 - COUNT($C$2:C38),RANK(C38,$C$2:$C$79,0) + COUNTIF($C$2:C38,C38) - 1) -> #DIV/0! | F38: =INDEX($A:$A, MATCH(G38, $B:$B, 0)) -> #N/A | G38: =INDEX($B$2:$B$79,MATCH(ROW()-1,$E$2:$E$79,0)) -> #N/A | H38: =IF(ISBLANK(D38),"",D38/Final!$W$4) -> #DIV/0! | I38: =IF(AND(INDEX($C$2:$C$79,MATCH(ROW()-1,$E$2:$E$79,0))=0,INDEX($D$2:$D$79,MATCH(ROW()-1,$E$2:$E$79,0))=0),"",INDEX($D$2:$D$79,MATCH(ROW()-1,$E$2:$E$79,0))) -> #N/A | J38: {=IF(COUNTIF($I$2:I38, I38)=1, _xlfn.TEXTJOIN(", ", TRUE, _xlfn.UNIQUE(_xlfn._xlws.FILTER($F$2:$F$79, $I$2:$I$79=I38, ""))), "")} | K38: {=IF(COUNTIF($I$2:I38,I38)=1,_xlfn.TEXTJOIN(", ",TRUE,IF($I$2:$I$79=I38,$G$2:$G$79,"")),"")} | L38: {=IF(COUNTIF($I$2:I38,I38)=1,I38,"")} | M38: {=IF(COUNTIF($H$2:H38,H38)=1,H38,"")}
A39: {=INDEX('Re-Final'!$Z$1:$CY$1, LOOKUP(ROW(A38), {1,14,58,67,73,76}, {1,14,58,67,73,76}))} -> B : Sewing | B39: =INDEX('Re-Final'!$Z$2:$CY$2, ROW()-ROW($B$2)+1) -> 25.Incorrect thread tension | C39: =IF(ISBLANK(D39),"",D39/'Re-Final'!$W$4) -> #DIV/0! | D39: =INDEX('Re-Final'!$Z$4:$CY$4, ROW()-ROW($D$2)+1) -> 0 | E39: =IF(C39="",COUNT($C$2:$C$79) + ROW()-ROW($C$2) + 1 - COUNT($C$2:C39),RANK(C39,$C$2:$C$79,0) + COUNTIF($C$2:C39,C39) - 1) -> #DIV/0! | F39: =INDEX($A:$A, MATCH(G39, $B:$B, 0)) -> #N/A | G39: =INDEX($B$2:$B$79,MATCH(ROW()-1,$E$2:$E$79,0)) -> #N/A | H39: =IF(ISBLANK(D39),"",D39/Final!$W$4) -> #DIV/0! | I39: =IF(AND(INDEX($C$2:$C$79,MATCH(ROW()-1,$E$2:$E$79,0))=0,INDEX($D$2:$D$79,MATCH(ROW()-1,$E$2:$E$79,0))=0),"",INDEX($D$2:$D$79,MATCH(ROW()-1,$E$2:$E$79,0))) -> #N/A
A40: {=INDEX('Re-Final'!$Z$1:$CY$1, LOOKUP(ROW(A39), {1,14,58,67,73,76}, {1,14,58,67,73,76}))} -> B : Sewing | B40: =INDEX('Re-Final'!$Z$2:$CY$2, ROW()-ROW($B$2)+1) -> 26.Falling off of a thread | C40: =IF(ISBLANK(D40),"",D40/'Re-Final'!$W$4) -> #DIV/0! | D40: =INDEX('Re-Final'!$Z$4:$CY$4, ROW()-ROW($D$2)+1) -> 0 | E40: =IF(C40="",COUNT($C$2:$C$79) + ROW()-ROW($C$2) + 1 - COUNT($C$2:C40),RANK(C40,$C$2:$C$79,0) + COUNTIF($C$2:C40,C40) - 1) -> #DIV/0! | F40: =INDEX($A:$A, MATCH(G40, $B:$B, 0)) -> #N/A | G40: =INDEX($B$2:$B$79,MATCH(ROW()-1,$E$2:$E$79,0)) -> #N/A | H40: =IF(ISBLANK(D40),"",D40/Final!$W$4) -> #DIV/0! | I40: =IF(AND(INDEX($C$2:$C$79,MATCH(ROW()-1,$E$2:$E$79,0))=0,INDEX($D$2:$D$79,MATCH(ROW()-1,$E$2:$E$79,0))=0),"",INDEX($D$2:$D$79,MATCH(ROW()-1,$E$2:$E$79,0))) -> #N/A
A41: {=INDEX('Re-Final'!$Z$1:$CY$1, LOOKUP(ROW(A40), {1,14,58,67,73,76}, {1,14,58,67,73,76}))} -> B : Sewing | B41: =INDEX('Re-Final'!$Z$2:$CY$2, ROW()-ROW($B$2)+1) -> 27.Lack of reverse stitch | C41: =IF(ISBLANK(D41),"",D41/'Re-Final'!$W$4) -> #DIV/0! | D41: =INDEX('Re-Final'!$Z$4:$CY$4, ROW()-ROW($D$2)+1) -> 0 | E41: =IF(C41="",COUNT($C$2:$C$79) + ROW()-ROW($C$2) + 1 - COUNT($C$2:C41),RANK(C41,$C$2:$C$79,0) + COUNTIF($C$2:C41,C41) - 1) -> #DIV/0! | F41: =INDEX($A:$A, MATCH(G41, $B:$B, 0)) -> #N/A | G41: =INDEX($B$2:$B$79,MATCH(ROW()-1,$E$2:$E$79,0)) -> #N/A | H41: =IF(ISBLANK(D41),"",D41/Final!$W$4) -> #DIV/0! | I41: =IF(AND(INDEX($C$2:$C$79,MATCH(ROW()-1,$E$2:$E$79,0))=0,INDEX($D$2:$D$79,MATCH(ROW()-1,$E$2:$E$79,0))=0),"",INDEX($D$2:$D$79,MATCH(ROW()-1,$E$2:$E$79,0))) -> #N/A
A42: {=INDEX('Re-Final'!$Z$1:$CY$1, LOOKUP(ROW(A41), {1,14,58,67,73,76}, {1,14,58,67,73,76}))} -> B : Sewing | B42: =INDEX('Re-Final'!$Z$2:$CY$2, ROW()-ROW($B$2)+1) -> 28.Incorrect easing | C42: =IF(ISBLANK(D42),"",D42/'Re-Final'!$W$4) -> #DIV/0! | D42: =INDEX('Re-Final'!$Z$4:$CY$4, ROW()-ROW($D$2)+1) -> 0 | E42: =IF(C42="",COUNT($C$2:$C$79) + ROW()-ROW($C$2) + 1 - COUNT($C$2:C42),RANK(C42,$C$2:$C$79,0) + COUNTIF($C$2:C42,C42) - 1) -> #DIV/0! | F42: =INDEX($A:$A, MATCH(G42, $B:$B, 0)) -> #N/A | G42: =INDEX($B$2:$B$79,MATCH(ROW()-1,$E$2:$E$79,0)) -> #N/A | H42: =IF(ISBLANK(D42),"",D42/Final!$W$4) -> #DIV/0! | I42: =IF(AND(INDEX($C$2:$C$79,MATCH(ROW()-1,$E$2:$E$79,0))=0,INDEX($D$2:$D$79,MATCH(ROW()-1,$E$2:$E$79,0))=0),"",INDEX($D$2:$D$79,MATCH(ROW()-1,$E$2:$E$79,0))) -> #N/A
A43: {=INDEX('Re-Final'!$Z$1:$CY$1, LOOKUP(ROW(A42), {1,14,58,67,73,76}, {1,14,58,67,73,76}))} -> B : Sewing | B43: =INDEX('Re-Final'!$Z$2:$CY$2, ROW()-ROW($B$2)+1) -> 29.Piecing defect | C43: =IF(ISBLANK(D43),"",D43/'Re-Final'!$W$4) -> #DIV/0! | D43: =INDEX('Re-Final'!$Z$4:$CY$4, ROW()-ROW($D$2)+1) -> 0 | E43: =IF(C43="",COUNT($C$2:$C$79) + ROW()-ROW($C$2) + 1 - COUNT($C$2:C43),RANK(C43,$C$2:$C$79,0) + COUNTIF($C$2:C43,C43) - 1) -> #DIV/0! | F43: =INDEX($A:$A, MATCH(G43, $B:$B, 0)) -> #N/A | G43: =INDEX($B$2:$B$79,MATCH(ROW()-1,$E$2:$E$79,0)) -> #N/A | H43: =IF(ISBLANK(D43),"",D43/Final!$W$4) -> #DIV/0! | I43: =IF(AND(INDEX($C$2:$C$79,MATCH(ROW()-1,$E$2:$E$79,0))=0,INDEX($D$2:$D$79,MATCH(ROW()-1,$E$2:$E$79,0))=0),"",INDEX($D$2:$D$79,MATCH(ROW()-1,$E$2:$E$79,0))) -> #N/A
A44: {=INDEX('Re-Final'!$Z$1:$CY$1, LOOKUP(ROW(A43), {1,14,58,67,73,76}, {1,14,58,67,73,76}))} -> B : Sewing | B44: =INDEX('Re-Final'!$Z$2:$CY$2, ROW()-ROW($B$2)+1) -> 30.Incorrect lapped seam | C44: =IF(ISBLANK(D44),"",D44/'Re-Final'!$W$4) -> #DIV/0! | D44: =INDEX('Re-Final'!$Z$4:$CY$4, ROW()-ROW($D$2)+1) -> 0 | E44: =IF(C44="",COUNT($C$2:$C$79) + ROW()-ROW($C$2) + 1 - COUNT($C$2:C44),RANK(C44,$C$2:$C$79,0) + COUNTIF($C$2:C44,C44) - 1) -> #DIV/0! | F44: =INDEX($A:$A, MATCH(G44, $B:$B, 0)) -> #N/A | G44: =INDEX($B$2:$B$79,MATCH(ROW()-1,$E$2:$E$79,0)) -> #N/A | H44: =IF(ISBLANK(D44),"",D44/Final!$W$4) -> #DIV/0! | I44: =IF(AND(INDEX($C$2:$C$79,MATCH(ROW()-1,$E$2:$E$79,0))=0,INDEX($D$2:$D$79,MATCH(ROW()-1,$E$2:$E$79,0))=0),"",INDEX($D$2:$D$79,MATCH(ROW()-1,$E$2:$E$79,0))) -> #N/A
A45: {=INDEX('Re-Final'!$Z$1:$CY$1, LOOKUP(ROW(A44), {1,14,58,67,73,76}, {1,14,58,67,73,76}))} -> B : Sewing | B45: =INDEX('Re-Final'!$Z$2:$CY$2, ROW()-ROW($B$2)+1) -> 31.Incorrect trimming | C45: =IF(ISBLANK(D45),"",D45/'Re-Final'!$W$4) -> #DIV/0! | D45: =INDEX('Re-Final'!$Z$4:$CY$4, ROW()-ROW($D$2)+1) -> 0 | E45: =IF(C45="",COUNT($C$2:$C$79) + ROW()-ROW($C$2) + 1 - COUNT($C$2:C45),RANK(C45,$C$2:$C$79,0) + COUNTIF($C$2:C45,C45) - 1) -> #DIV/0! | F45: =INDEX($A:$A, MATCH(G45, $B:$B, 0)) -> #N/A | G45: =INDEX($B$2:$B$79,MATCH(ROW()-1,$E$2:$E$79,0)) -> #N/A | H45: =IF(ISBLANK(D45),"",D45/Final!$W$4) -> #DIV/0! | I45: =IF(AND(INDEX($C$2:$C$79,MATCH(ROW()-1,$E$2:$E$79,0))=0,INDEX($D$2:$D$79,MATCH(ROW()-1,$E$2:$E$79,0))=0),"",INDEX($D$2:$D$79,MATCH(ROW()-1,$E$2:$E$79,0))) -> #N/A
A46: {=INDEX('Re-Final'!$Z$1:$CY$1, LOOKUP(ROW(A45), {1,14,58,67,73,76}, {1,14,58,67,73,76}))} -> B : Sewing | B46: =INDEX('Re-Final'!$Z$2:$CY$2, ROW()-ROW($B$2)+1) -> 32.Lack of strength | C46: =IF(ISBLANK(D46),"",D46/'Re-Final'!$W$4) -> #DIV/0! | D46: =INDEX('Re-Final'!$Z$4:$CY$4, ROW()-ROW($D$2)+1) -> 0 | E46: =IF(C46="",COUNT($C$2:$C$79) + ROW()-ROW($C$2) + 1 - COUNT($C$2:C46),RANK(C46,$C$2:$C$79,0) + COUNTIF($C$2:C46,C46) - 1) -> #DIV/0! | F46: =INDEX($A:$A, MATCH(G46, $B:$B, 0)) -> #N/A | G46: =INDEX($B$2:$B$79,MATCH(ROW()-1,$E$2:$E$79,0)) -> #N/A | H46: =IF(ISBLANK(D46),"",D46/Final!$W$4) -> #DIV/0! | I46: =IF(AND(INDEX($C$2:$C$79,MATCH(ROW()-1,$E$2:$E$79,0))=0,INDEX($D$2:$D$79,MATCH(ROW()-1,$E$2:$E$79,0))=0),"",INDEX($D$2:$D$79,MATCH(ROW()-1,$E$2:$E$79,0))) -> #N/A
A47: {=INDEX('Re-Final'!$Z$1:$CY$1, LOOKUP(ROW(A46), {1,14,58,67,73,76}, {1,14,58,67,73,76}))} -> B : Sewing | B47: =INDEX('Re-Final'!$Z$2:$CY$2, ROW()-ROW($B$2)+1) -> 33.Incorrect buttonhole sewing | C47: =IF(ISBLANK(D47),"",D47/'Re-Final'!$W$4) -> #DIV/0! | D47: =INDEX('Re-Final'!$Z$4:$CY$4, ROW()-ROW($D$2)+1) -> 0 | E47: =IF(C47="",COUNT($C$2:$C$79) + ROW()-ROW($C$2) + 1 - COUNT($C$2:C47),RANK(C47,$C$2:$C$79,0) + COUNTIF($C$2:C47,C47) - 1) -> #DIV/0! | F47: =INDEX($A:$A, MATCH(G47, $B:$B, 0)) -> #N/A | G47: =INDEX($B$2:$B$79,MATCH(ROW()-1,$E$2:$E$79,0)) -> #N/A | H47: =IF(ISBLANK(D47),"",D47/Final!$W$4) -> #DIV/0! | I47: =IF(AND(INDEX($C$2:$C$79,MATCH(ROW()-1,$E$2:$E$79,0))=0,INDEX($D$2:$D$79,MATCH(ROW()-1,$E$2:$E$79,0))=0),"",INDEX($D$2:$D$79,MATCH(ROW()-1,$E$2:$E$79,0))) -> #N/A
A48: {=INDEX('Re-Final'!$Z$1:$CY$1, LOOKUP(ROW(A47), {1,14,58,67,73,76}, {1,14,58,67,73,76}))} -> B : Sewing | B48: =INDEX('Re-Final'!$Z$2:$CY$2, ROW()-ROW($B$2)+1) -> 34.Incorrect brand label sewing | C48: =IF(ISBLANK(D48),"",D48/'Re-Final'!$W$4) -> #DIV/0! | D48: =INDEX('Re-Final'!$Z$4:$CY$4, ROW()-ROW($D$2)+1) -> 0 | E48: =IF(C48="",COUNT($C$2:$C$79) + ROW()-ROW($C$2) + 1 - COUNT($C$2:C48),RANK(C48,$C$2:$C$79,0) + COUNTIF($C$2:C48,C48) - 1) -> #DIV/0! | F48: =INDEX($A:$A, MATCH(G48, $B:$B, 0)) -> #N/A | G48: =INDEX($B$2:$B$79,MATCH(ROW()-1,$E$2:$E$79,0)) -> #N/A | H48: =IF(ISBLANK(D48),"",D48/Final!$W$4) -> #DIV/0! | I48: =IF(AND(INDEX($C$2:$C$79,MATCH(ROW()-1,$E$2:$E$79,0))=0,INDEX($D$2:$D$79,MATCH(ROW()-1,$E$2:$E$79,0))=0),"",INDEX($D$2:$D$79,MATCH(ROW()-1,$E$2:$E$79,0))) -> #N/A
